Workbook

Sheet 📋 Student Summary
A1: 📋 SHABAB BATCH 4 – STUDENT SUMMARY | All Parks | 2026-2027
A2: # | B2: Park | C2: Group | D2: Name | E2: Phone | F2: 📞 | G2: 💬 | H2: 📱Own | I2: Age | J2: Grade | K2: % Haazri | L2: P Count
A3: ="▶ Gulberg ("&SUMPRODUCT((LEN(D4:D76)>0)*1)&" students)" -> ▶ Gulberg (62 students)
A4: 1 | B4: Gulberg | C4: Group 1 | D4: =Gulberg!B26 -> Muhammad Umair | E4: =Gulberg!C26 -> '+923274088002 | F4: =IF(Gulberg!C26<>"",HYPERLINK("tel:"&SUBSTITUTE(SUBSTITUTE(Gulberg!C26,"+","+")," ",""),"📞"),"") -> 📞 | G4: =IF(Gulberg!C26<>"",HYPERLINK("https://wa.me/"&SUBSTITUTE(SUBSTITUTE(Gulberg!C26,"+","")," ",""),"💬"),"") -> 💬 | H4: =Gulberg!F26 | I4: =Gulberg!G26 -> 13.0 | J4: =Gulberg!H26 | K4: =Gulberg!CH26 -> 100% | L4: =Gulberg!CE26 -> 18
A5: 2 | B5: Gulberg | C5: Group 1 | D5: =Gulberg!B27 -> Muhammad Ahmad | E5: =Gulberg!C27 | F5: =IF(Gulberg!C27<>"",HYPERLINK("tel:"&SUBSTITUTE(SUBSTITUTE(Gulberg!C27,"+","+")," ",""),"📞"),"") | G5: =IF(Gulberg!C27<>"",HYPERLINK("https://wa.me/"&SUBSTITUTE(SUBSTITUTE(Gulberg!C27,"+","")," ",""),"💬"),"") | H5: =Gulberg!F27 | I5: =Gulberg!G27 -> 13.0 | J5: =Gulberg!H27 | K5: =Gulberg!CH27 -> 62% | L5: =Gulberg!CE27 -> 8
A6: 3 | B6: Gulberg | C6: Group 1 | D6: =Gulberg!B28 -> Muhammad Umar | E6: =Gulberg!C28 | F6: =IF(Gulberg!C28<>"",HYPERLINK("tel:"&SUBSTITUTE(SUBSTITUTE(Gulberg!C28,"+","+")," ",""),"📞"),"") | G6: =IF(Gulberg!C28<>"",HYPERLINK("https://wa.me/"&SUBSTITUTE(SUBSTITUTE(Gulberg!C28,"+","")," ",""),"💬"),"") | H6: =Gulberg!F28 | I6: =Gulberg!G28 -> 13.0 | J6: =Gulberg!H28 | K6: =Gulberg!CH28 -> 80% | L6: =Gulberg!CE28 -> 8
A7: 4 | B7: Gulberg | C7: Group 1 | D7: =Gulberg!B29 -> Muhammad Shoaib | E7: =Gulberg!C29 | F7: =IF(Gulberg!C29<>"",HYPERLINK("tel:"&SUBSTITUTE(SUBSTITUTE(Gulberg!C29,"+","+")," ",""),"📞"),"") | G7: =IF(Gulberg!C29<>"",HYPERLINK("https://wa.me/"&SUBSTITUTE(SUBSTITUTE(Gulberg!C29,"+","")," ",""),"💬"),"") | H7: =Gulberg!F29 | I7: =Gulberg!G29 -> 13.0 | J7: =Gulberg!H29 | K7: =Gulberg!CH29 -> 82% | L7: =Gulberg!CE29 -> 9
A8: 5 | B8: Gulberg | C8: Group 1 | D8: =Gulberg!B30 -> M Abdullah Qureshi | E8: =Gulberg!C30 | F8: =IF(Gulberg!C30<>"",HYPERLINK("tel:"&SUBSTITUTE(SUBSTITUTE(Gulberg!C30,"+","+")," ",""),"📞"),"") | G8: =IF(Gulberg!C30<>"",HYPERLINK("https://wa.me/"&SUBSTITUTE(SUBSTITUTE(Gulberg!C30,"+","")," ",""),"💬"),"") | H8: =Gulberg!F30 | I8: =Gulberg!G30 -> 14.0 | J8: =Gulberg!H30 -> 9th | K8: =Gulberg!CH30 -> 0% | L8: =Gulberg!CE30 -> 0
A9: 6 | B9: Gulberg | C9: Group 1 | D9: =Gulberg!B31 -> M.Moosa | E9: =Gulberg!C31 | F9: =IF(Gulberg!C31<>"",HYPERLINK("tel:"&SUBSTITUTE(SUBSTITUTE(Gulberg!C31,"+","+")," ",""),"📞"),"") | G9: =IF(Gulberg!C31<>"",HYPERLINK("https://wa.me/"&SUBSTITUTE(SUBSTITUTE(Gulberg!C31,"+","")," ",""),"💬"),"") | H9: =Gulberg!F31 | I9: =Gulberg!G31 -> 14.0 | J9: =Gulberg!H31 -> 10th | K9: =Gulberg!CH31 -> 100% | L9: =Gulberg!CE31 -> 18
A10: 7 | B10: Gulberg | C10: Group 1 | D10: =Gulberg!B32 -> Muhammad Abdullah Ahmad | E10: =Gulberg!C32 | F10: =IF(Gulberg!C32<>"",HYPERLINK("tel:"&SUBSTITUTE(SUBSTITUTE(Gulberg!C32,"+","+")," ",""),"📞"),"") | G10: =IF(Gulberg!C32<>"",HYPERLINK("https://wa.me/"&SUBSTITUTE(SUBSTITUTE(Gulberg!C32,"+","")," ",""),"💬"),"") | H10: =Gulberg!F32 | I10: =Gulberg!G32 -> 14.0 | J10: =Gulberg!H32 | K10: =Gulberg!CH32 -> 65% | L10: =Gulberg!CE32 -> 11
A11: 8 | B11: Gulberg | C11: Group 1 | D11: =Gulberg!B33 -> MUHAMMAD YOUSUF | E11: =Gulberg!C33 | F11: =IF(Gulberg!C33<>"",HYPERLINK("tel:"&SUBSTITUTE(SUBSTITUTE(Gulberg!C33,"+","+")," ",""),"📞"),"") | G11: =IF(Gulberg!C33<>"",HYPERLINK("https://wa.me/"&SUBSTITUTE(SUBSTITUTE(Gulberg!C33,"+","")," ",""),"💬"),"") | H11: =Gulberg!F33 | I11: =Gulberg!G33 -> 14.0 | J11: =Gulberg!H33 | K11: =Gulberg!CH33 -> 76% | L11: =Gulberg!CE33 -> 13
A12: 9 | B12: Gulberg | C12: Group 1 | D12: =Gulberg!B34 -> Muhammad Huzaifa saif | E12: =Gulberg!C34 -> '+923234977806 | F12: =IF(Gulberg!C34<>"",HYPERLINK("tel:"&SUBSTITUTE(SUBSTITUTE(Gulberg!C34,"+","+")," ",""),"📞"),"") -> 📞 | G12: =IF(Gulberg!C34<>"",HYPERLINK("https://wa.me/"&SUBSTITUTE(SUBSTITUTE(Gulberg!C34,"+","")," ",""),"💬"),"") -> 💬 | H12: =Gulberg!F34 | I12: =Gulberg!G34 -> 14.0 | J12: =Gulberg!H34 -> 9th | K12: =Gulberg!CH34 -> 94% | L12: =Gulberg!CE34 -> 16
A13: 10 | B13: Gulberg | C13: Group 1 | D13: =Gulberg!B35 -> Muhammad Yusha | E13: =Gulberg!C35 -> '+923334649728 | F13: =IF(Gulberg!C35<>"",HYPERLINK("tel:"&SUBSTITUTE(SUBSTITUTE(Gulberg!C35,"+","+")," ",""),"📞"),"") -> 📞 | G13: =IF(Gulberg!C35<>"",HYPERLINK("https://wa.me/"&SUBSTITUTE(SUBSTITUTE(Gulberg!C35,"+","")," ",""),"💬"),"") -> 💬 | H13: =Gulberg!F35 | I13: =Gulberg!G35 -> 14.0 | J13: =Gulberg!H35 -> 10th | K13: =Gulberg!CH35 -> 0% | L13: =Gulberg!CE35 -> 0
A14: 11 | B14: Gulberg | C14: Group 1 | D14: =Gulberg!B36 -> Muaz Zakariya Majid | E14: =Gulberg!C36 -> '+923334349783 | F14: =IF(Gulberg!C36<>"",HYPERLINK("tel:"&SUBSTITUTE(SUBSTITUTE(Gulberg!C36,"+","+")," ",""),"📞"),"") -> 📞 | G14: =IF(Gulberg!C36<>"",HYPERLINK("https://wa.me/"&SUBSTITUTE(SUBSTITUTE(Gulberg!C36,"+","")," ",""),"💬"),"") -> 💬 | H14: =Gulberg!F36 | I14: =Gulberg!G36 -> 14.0 | J14: =Gulberg!H36 -> Hafiz | K14: =Gulberg!CH36 -> 71% | L14: =Gulberg!CE36 -> 10
A15: 12 | B15: Gulberg | C15: Group 1 | D15: =Gulberg!B37 -> Muhammad Shaheer Shamsi | E15: =Gulberg!C37 -> '+923004188623 | F15: =IF(Gulberg!C37<>"",HYPERLINK("tel:"&SUBSTITUTE(SUBSTITUTE(Gulberg!C37,"+","+")," ",""),"📞"),"") -> 📞 | G15: =IF(Gulberg!C37<>"",HYPERLINK("https://wa.me/"&SUBSTITUTE(SUBSTITUTE(Gulberg!C37,"+","")," ",""),"💬"),"") -> 💬 | H15: =Gulberg!F37 | I15: =Gulberg!G37 -> 14.0 | J15: =Gulberg!H37 -> 9th | K15: =Gulberg!CH37 -> 88% | L15: =Gulberg!CE37 -> 15
... A21: 18 | B21: Gulberg | C21: Group 1 | D21: =Gulberg!B43 -> Abdul Moiz Shahid | E21: =Gulberg!C43 | F21: =IF(Gulberg!C43<>"",HYPERLINK("tel:"&SUBSTITUTE(SUBSTITUTE(Gulberg!C43,"+","+")," ",""),"📞"),"") | G21: =IF(Gulberg!C43<>"",HYPERLINK("https://wa.me/"&SUBSTITUTE(SUBSTITUTE(Gulberg!C43,"+","")," ",""),"💬"),"") | H21: =Gulberg!F43 | I21: =Gulberg!G43 | J21: =Gulberg!H43 | K21: =Gulberg!CH43 -> 44% | L21: =Gulberg!CE43 -> 4
A22: =IF(Gulberg!B44<>"",SUMPRODUCT((LEN(D4:D21)>0)*1)+1,"") -> 19 | B22: =IF(Gulberg!B44<>"","Gulberg","") -> Gulberg | C22: =IF(Gulberg!B44<>"","Group 1","") -> Group 1 | D22: =IF(Gulberg!B44<>"",Gulberg!B44,"") -> Arham | E22: =IF(Gulberg!B44<>"",Gulberg!C44,"") | F22: =IF(Gulberg!B44<>"",HYPERLINK("tel:"&SUBSTITUTE(SUBSTITUTE(Gulberg!C44,"+","+")," ",""),"📞"),"") -> 📞 | G22: =IF(Gulberg!B44<>"",HYPERLINK("https://wa.me/"&SUBSTITUTE(SUBSTITUTE(Gulberg!C44,"+","")," ",""),"💬"),"") -> 💬 | H22: =IF(Gulberg!B44<>"",Gulberg!F44,"") | I22: =IF(Gulberg!B44<>"",Gulberg!G44,"") -> 14 | J22: =IF(Gulberg!B44<>"",Gulberg!H44,"") | K22: =IF(Gulberg!B44<>"",Gulberg!CH44,"") -> 20% | L22: =IF(Gulberg!B44<>"",Gulberg!CE44,"") -> 1
A23: =IF(Gulberg!B45<>"",SUMPRODUCT((LEN(D4:D22)>0)*1)+1,"") -> 20 | B23: =IF(Gulberg!B45<>"","Gulberg","") -> Gulberg | C23: =IF(Gulberg!B45<>"","Group 1","") -> Group 1 | D23: =IF(Gulberg!B45<>"",Gulberg!B45,"") -> Muhammad Usama | E23: =IF(Gulberg!B45<>"",Gulberg!C45,"") -> +923171852200 | F23: =IF(Gulberg!B45<>"",HYPERLINK("tel:"&SUBSTITUTE(SUBSTITUTE(Gulberg!C45,"+","+")," ",""),"📞"),"") -> 📞 | G23: =IF(Gulberg!B45<>"",HYPERLINK("https://wa.me/"&SUBSTITUTE(SUBSTITUTE(Gulberg!C45,"+","")," ",""),"💬"),"") -> 💬 | H23: =IF(Gulberg!B45<>"",Gulberg!F45,"") | I23: =IF(Gulberg!B45<>"",Gulberg!G45,"") -> 14 | J23: =IF(Gulberg!B45<>"",Gulberg!H45,"") | K23: =IF(Gulberg!B45<>"",Gulberg!CH45,"") -> 100% | L23: =IF(Gulberg!B45<>"",Gulberg!CE45,"") -> 2
A24: =IF(Gulberg!B46<>"",SUMPRODUCT((LEN(D4:D23)>0)*1)+1,"") | B24: =IF(Gulberg!B46<>"","Gulberg","") | C24: =IF(Gulberg!B46<>"","Group 1","") | D24: =IF(Gulberg!B46<>"",Gulberg!B46,"") | E24: =IF(Gulberg!B46<>"",Gulberg!C46,"") | F24: =IF(Gulberg!B46<>"",HYPERLINK("tel:"&SUBSTITUTE(SUBSTITUTE(Gulberg!C46,"+","+")," ",""),"📞"),"") | G24: =IF(Gulberg!B46<>"",HYPERLINK("https://wa.me/"&SUBSTITUTE(SUBSTITUTE(Gulberg!C46,"+","")," ",""),"💬"),"") | H24: =IF(Gulberg!B46<>"",Gulberg!F46,"") | I24: =IF(Gulberg!B46<>"",Gulberg!G46,"") | J24: =IF(Gulberg!B46<>"",Gulberg!H46,"") | K24: =IF(Gulberg!B46<>"",Gulberg!CH46,"") | L24: =IF(Gulberg!B46<>"",Gulberg!CE46,"")
A25: =IF(Gulberg!B47<>"",SUMPRODUCT((LEN(D4:D24)>0)*1)+1,"") | B25: =IF(Gulberg!B47<>"","Gulberg","") | C25: =IF(Gulberg!B47<>"","Group 1","") | D25: =IF(Gulberg!B47<>"",Gulberg!B47,"") | E25: =IF(Gulberg!B47<>"",Gulberg!C47,"") | F25: =IF(Gulberg!B47<>"",HYPERLINK("tel:"&SUBSTITUTE(SUBSTITUTE(Gulberg!C47,"+","+")," ",""),"📞"),"") | G25: =IF(Gulberg!B47<>"",HYPERLINK("https://wa.me/"&SUBSTITUTE(SUBSTITUTE(Gulberg!C47,"+","")," ",""),"💬"),"") | H25: =IF(Gulberg!B47<>"",Gulberg!F47,"") | I25: =IF(Gulberg!B47<>"",Gulberg!G47,"") | J25: =IF(Gulberg!B47<>"",Gulberg!H47,"") | K25: =IF(Gulberg!B47<>"",Gulberg!CH47,"") | L25: =IF(Gulberg!B47<>"",Gulberg!CE47,"")
A26: =IF(Gulberg!B48<>"",SUMPRODUCT((LEN(D4:D25)>0)*1)+1,"") | B26: =IF(Gulberg!B48<>"","Gulberg","") | C26: =IF(Gulberg!B48<>"","Group 1","") | D26: =IF(Gulberg!B48<>"",Gulberg!B48,"") | E26: =IF(Gulberg!B48<>"",Gulberg!C48,"") | F26: =IF(Gulberg!B48<>"",HYPERLINK("tel:"&SUBSTITUTE(SUBSTITUTE(Gulberg!C48,"+","+")," ",""),"📞"),"") | G26: =IF(Gulberg!B48<>"",HYPERLINK("https://wa.me/"&SUBSTITUTE(SUBSTITUTE(Gulberg!C48,"+","")," ",""),"💬"),"") | H26: =IF(Gulberg!B48<>"",Gulberg!F48,"") | I26: =IF(Gulberg!B48<>"",Gulberg!G48,"") | J26: =IF(Gulberg!B48<>"",Gulberg!H48,"") | K26: =IF(Gulberg!B48<>"",Gulberg!CH48,"") | L26: =IF(Gulberg!B48<>"",Gulberg!CE48,"")
A27: 19 | B27: Gulberg | C27: Group 2 | D27: =Gulberg!B52 -> Muhammad Humayl Ali | E27: =Gulberg!C52 -> '+923008492494 | F27: =IF(Gulberg!C52<>"",HYPERLINK("tel:"&SUBSTITUTE(SUBSTITUTE(Gulberg!C52,"+","+")," ",""),"📞"),"") -> 📞 | G27: =IF(Gulberg!C52<>"",HYPERLINK("https://wa.me/"&SUBSTITUTE(SUBSTITUTE(Gulberg!C52,"+","")," ",""),"💬"),"") -> 💬 | H27: =Gulberg!F52 | I27: =Gulberg!G52 -> 15.0 | J27: =Gulberg!H52 | K27: =Gulberg!CH52 -> 72% | L27: =Gulberg!CE52 -> 13
A28: 20 | B28: Gulberg | C28: Group 2 | D28: =Gulberg!B53 -> Maaz Tahir | E28: =Gulberg!C53 -> '+923090809644 | F28: =IF(Gulberg!C53<>"",HYPERLINK("tel:"&SUBSTITUTE(SUBSTITUTE(Gulberg!C53,"+","+")," ",""),"📞"),"") -> 📞 | G28: =IF(Gulberg!C53<>"",HYPERLINK("https://wa.me/"&SUBSTITUTE(SUBSTITUTE(Gulberg!C53,"+","")," ",""),"💬"),"") -> 💬 | H28: =Gulberg!F53 | I28: =Gulberg!G53 -> 15.0 | J28: =Gulberg!H53 -> 9th | K28: =Gulberg!CH53 -> 78% | L28: =Gulberg!CE53 -> 14
A29: 21 | B29: Gulberg | C29: Group 2 | D29: =Gulberg!B54 -> M. Awais Zafar | E29: =Gulberg!C54 -> '+923114333457 | F29: =IF(Gulberg!C54<>"",HYPERLINK("tel:"&SUBSTITUTE(SUBSTITUTE(Gulberg!C54,"+","+")," ",""),"📞"),"") -> 📞 | G29: =IF(Gulberg!C54<>"",HYPERLINK("https://wa.me/"&SUBSTITUTE(SUBSTITUTE(Gulberg!C54,"+","")," ",""),"💬"),"") -> 💬 | H29: =Gulberg!F54 | I29: =Gulberg!G54 -> 16.0 | J29: =Gulberg!H54 -> 10th | K29: =Gulberg!CH54 -> 78% | L29: =Gulberg!CE54 -> 14
A30: 22 | B30: Gulberg | C30: Group 2 | D30: =Gulberg!B55 -> Muhammad Abdullah | E30: =Gulberg!C55 -> '+923274963532 | F30: =IF(Gulberg!C55<>"",HYPERLINK("tel:"&SUBSTITUTE(SUBSTITUTE(Gulberg!C55,"+","+")," ",""),"📞"),"") -> 📞 | G30: =IF(Gulberg!C55<>"",HYPERLINK("https://wa.me/"&SUBSTITUTE(SUBSTITUTE(Gulberg!C55,"+","")," ",""),"💬"),"") -> 💬 | H30: =Gulberg!F55 | I30: =Gulberg!G55 -> 16.0 | J30: =Gulberg!H55 -> 10th | K30: =Gulberg!CH55 -> 0% | L30: =Gulberg!CE55 -> 0
A31: 23 | B31: Gulberg | C31: Group 2 | D31: =Gulberg!B56 -> Ans Ramzan | E31: =Gulberg!C56 -> '+923285865741 | F31: =IF(Gulberg!C56<>"",HYPERLINK("tel:"&SUBSTITUTE(SUBSTITUTE(Gulberg!C56,"+","+")," ",""),"📞"),"") -> 📞 | G31: =IF(Gulberg!C56<>"",HYPERLINK("https://wa.me/"&SUBSTITUTE(SUBSTITUTE(Gulberg!C56,"+","")," ",""),"💬"),"") -> 💬 | H31: =Gulberg!F56 | I31: =Gulberg!G56 -> 16.0 | J31: =Gulberg!H56 | K31: =Gulberg!CH56 -> 0% | L31: =Gulberg!CE56 -> 0
A32: 24 | B32: Gulberg | C32: Group 2 | D32: =Gulberg!B57 -> M. Ali Nasir | E32: =Gulberg!C57 -> '+923214151591 | F32: =IF(Gulberg!C57<>"",HYPERLINK("tel:"&SUBSTITUTE(SUBSTITUTE(Gulberg!C57,"+","+")," ",""),"📞"),"") -> 📞 | G32: =IF(Gulberg!C57<>"",HYPERLINK("https://wa.me/"&SUBSTITUTE(SUBSTITUTE(Gulberg!C57,"+","")," ",""),"💬"),"") -> 💬 | H32: =Gulberg!F57 | I32: =Gulberg!G57 -> 16.0 | J32: =Gulberg!H57 -> O Level | K32: =Gulberg!CH57 -> 28% | L32: =Gulberg!CE57 -> 5
A33: 25 | B33: Gulberg | C33: Group 2 | D33: =Gulberg!B58 -> M.wahaj Ahmed | E33: =Gulberg!C58 -> '+923215845260 | F33: =IF(Gulberg!C58<>"",HYPERLINK("tel:"&SUBSTITUTE(SUBSTITUTE(Gulberg!C58,"+","+")," ",""),"📞"),"") -> 📞 | G33: =IF(Gulberg!C58<>"",HYPERLINK("https://wa.me/"&SUBSTITUTE(SUBSTITUTE(Gulberg!C58,"+","")," ",""),"💬"),"") -> 💬 | H33: =Gulberg!F58 | I33: =Gulberg!G58 -> 16.0 | J33: =Gulberg!H58 -> 10th | K33: =Gulberg!CH58 -> 100% | L33: =Gulberg!CE58 -> 15
A34: 26 | B34: Gulberg | C34: Group 2 | D34: =Gulberg!B59 -> Abdur Rehman Yahya | E34: =Gulberg!C59 -> '+923259753363 | F34: =IF(Gulberg!C59<>"",HYPERLINK("tel:"&SUBSTITUTE(SUBSTITUTE(Gulberg!C59,"+","+")," ",""),"📞"),"") -> 📞 | G34: =IF(Gulberg!C59<>"",HYPERLINK("https://wa.me/"&SUBSTITUTE(SUBSTITUTE(Gulberg!C59,"+","")," ",""),"💬"),"") -> 💬 | H34: =Gulberg!F59 | I34: =Gulberg!G59 -> 16.0 | J34: =Gulberg!H59 -> 11th | K34: =Gulberg!CH59 -> 77% | L34: =Gulberg!CE59 -> 10
A35: 27 | B35: Gulberg | C35: Group 2 | D35: =Gulberg!B60 -> Zawar hussain | E35: =Gulberg!C60 -> '+923230011678 | F35: =IF(Gulberg!C60<>"",HYPERLINK("tel:"&SUBSTITUTE(SUBSTITUTE(Gulberg!C60,"+","+")," ",""),"📞"),"") -> 📞 | G35: =IF(Gulberg!C60<>"",HYPERLINK("https://wa.me/"&SUBSTITUTE(SUBSTITUTE(Gulberg!C60,"+","")," ",""),"💬"),"") -> 💬 | H35: =Gulberg!F60 | I35: =Gulberg!G60 -> 16.0 | J35: =Gulberg!H60 | K35: =Gulberg!CH60 -> 56% | L35: =Gulberg!CE60 -> 9
A36: 28 | B36: Gulberg | C36: Group 2 | D36: =Gulberg!B61 -> Hamza Muslim | E36: =Gulberg!C61 -> '+923288183734 | F36: =IF(Gulberg!C61<>"",HYPERLINK("tel:"&SUBSTITUTE(SUBSTITUTE(Gulberg!C61,"+","+")," ",""),"📞"),"") -> 📞 | G36: =IF(Gulberg!C61<>"",HYPERLINK("https://wa.me/"&SUBSTITUTE(SUBSTITUTE(Gulberg!C61,"+","")," ",""),"💬"),"") -> 💬 | H36: =Gulberg!F61 | I36: =Gulberg!G61 -> 16.0 | J36: =Gulberg!H61 | K36: =Gulberg!CH61 -> 53% | L36: =Gulberg!CE61 -> 8
A37: 29 | B37: Gulberg | C37: Group 2 | D37: =Gulberg!B62 -> Muhammad Azaan | E37: =Gulberg!C62 -> '+923095376062 | F37: =IF(Gulberg!C62<>"",HYPERLINK("tel:"&SUBSTITUTE(SUBSTITUTE(Gulberg!C62,"+","+")," ",""),"📞"),"") -> 📞 | G37: =IF(Gulberg!C62<>"",HYPERLINK("https://wa.me/"&SUBSTITUTE(SUBSTITUTE(Gulberg!C62,"+","")," ",""),"💬"),"") -> 💬 | H37: =Gulberg!F62 | I37: =Gulberg!G62 -> 17.0 | J37: =Gulberg!H62 | K37: =Gulberg!CH62 -> 22% | L37: =Gulberg!CE62 -> 2
A38: 30 | B38: Gulberg | C38: Group 2 | D38: =Gulberg!B63 -> Mohammad Zain Ghani | E38: =Gulberg!C63 -> '+923043337555 | F38: =IF(Gulberg!C63<>"",HYPERLINK("tel:"&SUBSTITUTE(SUBSTITUTE(Gulberg!C63,"+","+")," ",""),"📞"),"") -> 📞 | G38: =IF(Gulberg!C63<>"",HYPERLINK("https://wa.me/"&SUBSTITUTE(SUBSTITUTE(Gulberg!C63,"+","")," ",""),"💬"),"") -> 💬 | H38: =Gulberg!F63 | I38: =Gulberg!G63 -> 16.0 | J38: =Gulberg!H63 | K38: =Gulberg!CH63 -> 80% | L38: =Gulberg!CE63 -> 12
... A48: 40 | B48: Gulberg | C48: Group 2 | D48: =Gulberg!B73 -> Noman bin Saif | E48: =Gulberg!C73 | F48: =IF(Gulberg!C73<>"",HYPERLINK("tel:"&SUBSTITUTE(SUBSTITUTE(Gulberg!C73,"+","+")," ",""),"📞"),"") | G48: =IF(Gulberg!C73<>"",HYPERLINK("https://wa.me/"&SUBSTITUTE(SUBSTITUTE(Gulberg!C73,"+","")," ",""),"💬"),"") | H48: =Gulberg!F73 | I48: =Gulberg!G73 | J48: =Gulberg!H73 | K48: =Gulberg!CH73 -> 100% | L48: =Gulberg!CE73 -> 3
A49: =IF(Gulberg!B74<>"",SUMPRODUCT((LEN(D4:D48)>0)*1)+1,"") -> 43 | B49: =IF(Gulberg!B74<>"","Gulberg","") -> Gulberg | C49: =IF(Gulberg!B74<>"","Group 2","") -> Group 2 | D49: =IF(Gulberg!B74<>"",Gulberg!B74,"") -> Muhammad Awais | E49: =IF(Gulberg!B74<>"",Gulberg!C74,"") -> +923214551484 | F49: =IF(Gulberg!B74<>"",HYPERLINK("tel:"&SUBSTITUTE(SUBSTITUTE(Gulberg!C74,"+","+")," ",""),"📞"),"") -> 📞 | G49: =IF(Gulberg!B74<>"",HYPERLINK("https://wa.me/"&SUBSTITUTE(SUBSTITUTE(Gulberg!C74,"+","")," ",""),"💬"),"") -> 💬 | H49: =IF(Gulberg!B74<>"",Gulberg!F74,"") | I49: =IF(Gulberg!B74<>"",Gulberg!G74,"") -> 16 | J49: =IF(Gulberg!B74<>"",Gulberg!H74,"") | K49: =IF(Gulberg!B74<>"",Gulberg!CH74,"") -> 100% | L49: =IF(Gulberg!B74<>"",Gulberg!CE74,"") -> 1
A50: =IF(Gulberg!B75<>"",SUMPRODUCT((LEN(D4:D49)>0)*1)+1,"") | B50: =IF(Gulberg!B75<>"","Gulberg","") | C50: =IF(Gulberg!B75<>"","Group 2","") | D50: =IF(Gulberg!B75<>"",Gulberg!B75,"") | E50: =IF(Gulberg!B75<>"",Gulberg!C75,"") | F50: =IF(Gulberg!B75<>"",HYPERLINK("tel:"&SUBSTITUTE(SUBSTITUTE(Gulberg!C75,"+","+")," ",""),"📞"),"") | G50: =IF(Gulberg!B75<>"",HYPERLINK("https://wa.me/"&SUBSTITUTE(SUBSTITUTE(Gulberg!C75,"+","")," ",""),"💬"),"") | H50: =IF(Gulberg!B75<>"",Gulberg!F75,"") | I50: =IF(Gulberg!B75<>"",Gulberg!G75,"") | J50: =IF(Gulberg!B75<>"",Gulberg!H75,"") | K50: =IF(Gulberg!B75<>"",Gulberg!CH75,"") | L50: =IF(Gulberg!B75<>"",Gulberg!CE75,"")
A51: =IF(Gulberg!B76<>"",SUMPRODUCT((LEN(D4:D50)>0)*1)+1,"") | B51: =IF(Gulberg!B76<>"","Gulberg","") | C51: =IF(Gulberg!B76<>"","Group 2","") | D51: =IF(Gulberg!B76<>"",Gulberg!B76,"") | E51: =IF(Gulberg!B76<>"",Gulberg!C76,"") | F51: =IF(Gulberg!B76<>"",HYPERLINK("tel:"&SUBSTITUTE(SUBSTITUTE(Gulberg!C76,"+","+")," ",""),"📞"),"") | G51: =IF(Gulberg!B76<>"",HYPERLINK("https://wa.me/"&SUBSTITUTE(SUBSTITUTE(Gulberg!C76,"+","")," ",""),"💬"),"") | H51: =IF(Gulberg!B76<>"",Gulberg!F76,"") | I51: =IF(Gulberg!B76<>"",Gulberg!G76,"") | J51: =IF(Gulberg!B76<>"",Gulberg!H76,"") | K51: =IF(Gulberg!B76<>"",Gulberg!CH76,"") | L51: =IF(Gulberg!B76<>"",Gulberg!CE76,"")
A52: =IF(Gulberg!B77<>"",SUMPRODUCT((LEN(D4:D51)>0)*1)+1,"") | B52: =IF(Gulberg!B77<>"","Gulberg","") | C52: =IF(Gulberg!B77<>"","Group 2","") | D52: =IF(Gulberg!B77<>"",Gulberg!B77,"") | E52: =IF(Gulberg!B77<>"",Gulberg!C77,"") | F52: =IF(Gulberg!B77<>"",HYPERLINK("tel:"&SUBSTITUTE(SUBSTITUTE(Gulberg!C77,"+","+")," ",""),"📞"),"") | G52: =IF(Gulberg!B77<>"",HYPERLINK("https://wa.me/"&SUBSTITUTE(SUBSTITUTE(Gulberg!C77,"+","")," ",""),"💬"),"") | H52: =IF(Gulberg!B77<>"",Gulberg!F77,"") | I52: =IF(Gulberg!B77<>"",Gulberg!G77,"") | J52: =IF(Gulberg!B77<>"",Gulberg!H77,"") | K52: =IF(Gulberg!B77<>"",Gulberg!CH77,"") | L52: =IF(Gulberg!B77<>"",Gulberg!CE77,"")
A53: =IF(Gulberg!B78<>"",SUMPRODUCT((LEN(D4:D52)>0)*1)+1,"") | B53: =IF(Gulberg!B78<>"","Gulberg","") | C53: =IF(Gulberg!B78<>"","Group 2","") | D53: =IF(Gulberg!B78<>"",Gulberg!B78,"") | E53: =IF(Gulberg!B78<>"",Gulberg!C78,"") | F53: =IF(Gulberg!B78<>"",HYPERLINK("tel:"&SUBSTITUTE(SUBSTITUTE(Gulberg!C78,"+","+")," ",""),"📞"),"") | G53: =IF(Gulberg!B78<>"",HYPERLINK("https://wa.me/"&SUBSTITUTE(SUBSTITUTE(Gulberg!C78,"+","")," ",""),"💬"),"") | H53: =IF(Gulberg!B78<>"",Gulberg!F78,"") | I53: =IF(Gulberg!B78<>"",Gulberg!G78,"") | J53: =IF(Gulberg!B78<>"",Gulberg!H78,"") | K53: =IF(Gulberg!B78<>"",Gulberg!CH78,"") | L53: =IF(Gulberg!B78<>"",Gulberg!CE78,"")
A54: 41 | B54: Gulberg | C54: Group 3 | D54: =Gulberg!B82 -> Muhammad Talal | E54: =Gulberg!C82 -> '+923289779626 | F54: =IF(Gulberg!C82<>"",HYPERLINK("tel:"&SUBSTITUTE(SUBSTITUTE(Gulberg!C82,"+","+")," ",""),"📞"),"") -> 📞 | G54: =IF(Gulberg!C82<>"",HYPERLINK("https://wa.me/"&SUBSTITUTE(SUBSTITUTE(Gulberg!C82,"+","")," ",""),"💬"),"") -> 💬 | H54: =Gulberg!F82 | I54: =Gulberg!G82 -> 17.0 | J54: =Gulberg!H82 | K54: =Gulberg!CH82 -> 11% | L54: =Gulberg!CE82 -> 1
...

Sheet Sheet1

Sheet 👨‍🏫 Murabbi Summary
A1: 👨‍🏫 MURABBIS – PARK-WISE SUMMARY | Batch 4 | 2026-2027
A2: Live data — naam likhne pe automatically appear ho jaayega
A3: # | B3: Park | C3: Murabbi Naam | D3: Phone | E3: 📞 | F3: 💬 | G3: Total P | H3: Total A | I3: Total L | J3: % Haazri | K3: Classes | L3: Status
A4: ="▶ Gulberg — "&SUMPRODUCT((LEN(C5:C19)>0)*1)&" Murabbis" -> ▶ Gulberg — 15 Murabbis
A5: 1 | B5: Gulberg | C5: =Gulberg!B9 -> Hasnain Zafar | D5: =Gulberg!C9 -> '+923060221997 | E5: =IF(Gulberg!C9<>"",HYPERLINK("tel:"&SUBSTITUTE(SUBSTITUTE(Gulberg!C9,"+","+")," ",""),"📞"),"") -> 📞 | F5: =IF(Gulberg!C9<>"",HYPERLINK("https://wa.me/"&SUBSTITUTE(SUBSTITUTE(Gulberg!C9,"+","")," ",""),"💬"),"") -> 💬 | G5: =Gulberg!CE9 -> 18 | H5: =Gulberg!CF9 -> 0 | I5: =Gulberg!CG9 -> 0 | J5: =Gulberg!CH9 -> 100% | K5: =COUNTA(Gulberg!I9:CD9)-COUNTIF(Gulberg!I9:CD9,"OFF") -> 72 | L5: =IF(G5+H5=0,"No Data",IF(G5/(G5+H5)>=0.9,"✅ Excellent",IF(G5/(G5+H5)>=0.75,"🟡 Good",IF(G5/(G5+H5)>=0.6,"🟠 Average","🔴 Low")))) -> ✅ Excellent
A6: 2 | B6: Gulberg | C6: =Gulberg!B10 -> Hanzala Tauseef | D6: =Gulberg!C10 -> '+923047178171 | E6: =IF(Gulberg!C10<>"",HYPERLINK("tel:"&SUBSTITUTE(SUBSTITUTE(Gulberg!C10,"+","+")," ",""),"📞"),"") -> 📞 | F6: =IF(Gulberg!C10<>"",HYPERLINK("https://wa.me/"&SUBSTITUTE(SUBSTITUTE(Gulberg!C10,"+","")," ",""),"💬"),"") -> 💬 | G6: =Gulberg!CE10 -> 18 | H6: =Gulberg!CF10 -> 0 | I6: =Gulberg!CG10 -> 0 | J6: =Gulberg!CH10 -> 100% | K6: =COUNTA(Gulberg!I10:CD10)-COUNTIF(Gulberg!I10:CD10,"OFF") -> 72 | L6: =IF(G6+H6=0,"No Data",IF(G6/(G6+H6)>=0.9,"✅ Excellent",IF(G6/(G6+H6)>=0.75,"🟡 Good",IF(G6/(G6+H6)>=0.6,"🟠 Average","🔴 Low")))) -> ✅ Excellent
A7: 3 | B7: Gulberg | C7: =Gulberg!B11 -> Ikram Meer | D7: =Gulberg!C11 -> '+923364543324 | E7: =IF(Gulberg!C11<>"",HYPERLINK("tel:"&SUBSTITUTE(SUBSTITUTE(Gulberg!C11,"+","+")," ",""),"📞"),"") -> 📞 | F7: =IF(Gulberg!C11<>"",HYPERLINK("https://wa.me/"&SUBSTITUTE(SUBSTITUTE(Gulberg!C11,"+","")," ",""),"💬"),"") -> 💬 | G7: =Gulberg!CE11 -> 18 | H7: =Gulberg!CF11 -> 0 | I7: =Gulberg!CG11 -> 0 | J7: =Gulberg!CH11 -> 100% | K7: =COUNTA(Gulberg!I11:CD11)-COUNTIF(Gulberg!I11:CD11,"OFF") -> 72 | L7: =IF(G7+H7=0,"No Data",IF(G7/(G7+H7)>=0.9,"✅ Excellent",IF(G7/(G7+H7)>=0.75,"🟡 Good",IF(G7/(G7+H7)>=0.6,"🟠 Average","🔴 Low")))) -> ✅ Excellent
A8: 4 | B8: Gulberg | C8: =Gulberg!B12 -> Imran Amin | D8: =Gulberg!C12 -> '+923294368993 | E8: =IF(Gulberg!C12<>"",HYPERLINK("tel:"&SUBSTITUTE(SUBSTITUTE(Gulberg!C12,"+","+")," ",""),"📞"),"") -> 📞 | F8: =IF(Gulberg!C12<>"",HYPERLINK("https://wa.me/"&SUBSTITUTE(SUBSTITUTE(Gulberg!C12,"+","")," ",""),"💬"),"") -> 💬 | G8: =Gulberg!CE12 -> 17 | H8: =Gulberg!CF12 -> 1 | I8: =Gulberg!CG12 -> 0 | J8: =Gulberg!CH12 -> 94% | K8: =COUNTA(Gulberg!I12:CD12)-COUNTIF(Gulberg!I12:CD12,"OFF") -> 72 | L8: =IF(G8+H8=0,"No Data",IF(G8/(G8+H8)>=0.9,"✅ Excellent",IF(G8/(G8+H8)>=0.75,"🟡 Good",IF(G8/(G8+H8)>=0.6,"🟠 Average","🔴 Low")))) -> ✅ Excellent
A9: 5 | B9: Gulberg | C9: =Gulberg!B13 -> Hammad Raza | D9: =Gulberg!C13 -> '+923220774124 | E9: =IF(Gulberg!C13<>"",HYPERLINK("tel:"&SUBSTITUTE(SUBSTITUTE(Gulberg!C13,"+","+")," ",""),"📞"),"") -> 📞 | F9: =IF(Gulberg!C13<>"",HYPERLINK("https://wa.me/"&SUBSTITUTE(SUBSTITUTE(Gulberg!C13,"+","")," ",""),"💬"),"") -> 💬 | G9: =Gulberg!CE13 -> 18 | H9: =Gulberg!CF13 -> 0 | I9: =Gulberg!CG13 -> 0 | J9: =Gulberg!CH13 -> 100% | K9: =COUNTA(Gulberg!I13:CD13)-COUNTIF(Gulberg!I13:CD13,"OFF") -> 72 | L9: =IF(G9+H9=0,"No Data",IF(G9/(G9+H9)>=0.9,"✅ Excellent",IF(G9/(G9+H9)>=0.75,"🟡 Good",IF(G9/(G9+H9)>=0.6,"🟠 Average","🔴 Low")))) -> ✅ Excellent
A10: 6 | B10: Gulberg | C10: =Gulberg!B14 -> Basit Ahsan | D10: =Gulberg!C14 -> '+923226720331 | E10: =IF(Gulberg!C14<>"",HYPERLINK("tel:"&SUBSTITUTE(SUBSTITUTE(Gulberg!C14,"+","+")," ",""),"📞"),"") -> 📞 | F10: =IF(Gulberg!C14<>"",HYPERLINK("https://wa.me/"&SUBSTITUTE(SUBSTITUTE(Gulberg!C14,"+","")," ",""),"💬"),"") -> 💬 | G10: =Gulberg!CE14 -> 18 | H10: =Gulberg!CF14 -> 0 | I10: =Gulberg!CG14 -> 0 | J10: =Gulberg!CH14 -> 100% | K10: =COUNTA(Gulberg!I14:CD14)-COUNTIF(Gulberg!I14:CD14,"OFF") -> 72 | L10: =IF(G10+H10=0,"No Data",IF(G10/(G10+H10)>=0.9,"✅ Excellent",IF(G10/(G10+H10)>=0.75,"🟡 Good",IF(G10/(G10+H10)>=0.6,"🟠 Average","🔴 Low")))) -> ✅ Excellent
A11: 7 | B11: Gulberg | C11: =Gulberg!B15 -> Abdul Kabeer | D11: =Gulberg!C15 -> '+923244190830 | E11: =IF(Gulberg!C15<>"",HYPERLINK("tel:"&SUBSTITUTE(SUBSTITUTE(Gulberg!C15,"+","+")," ",""),"📞"),"") -> 📞 | F11: =IF(Gulberg!C15<>"",HYPERLINK("https://wa.me/"&SUBSTITUTE(SUBSTITUTE(Gulberg!C15,"+","")," ",""),"💬"),"") -> 💬 | G11: =Gulberg!CE15 -> 15 | H11: =Gulberg!CF15 -> 1 | I11: =Gulberg!CG15 -> 2 | J11: =Gulberg!CH15 -> 94% | K11: =COUNTA(Gulberg!I15:CD15)-COUNTIF(Gulberg!I15:CD15,"OFF") -> 72 | L11: =IF(G11+H11=0,"No Data",IF(G11/(G11+H11)>=0.9,"✅ Excellent",IF(G11/(G11+H11)>=0.75,"🟡 Good",IF(G11/(G11+H11)>=0.6,"🟠 Average","🔴 Low")))) -> ✅ Excellent
A12: 8 | B12: Gulberg | C12: =Gulberg!B16 -> Abdul Rehman Munir | D12: =Gulberg!C16 -> '+923080114534 | E12: =IF(Gulberg!C16<>"",HYPERLINK("tel:"&SUBSTITUTE(SUBSTITUTE(Gulberg!C16,"+","+")," ",""),"📞"),"") -> 📞 | F12: =IF(Gulberg!C16<>"",HYPERLINK("https://wa.me/"&SUBSTITUTE(SUBSTITUTE(Gulberg!C16,"+","")," ",""),"💬"),"") -> 💬 | G12: =Gulberg!CE16 -> 16 | H12: =Gulberg!CF16 -> 0 | I12: =Gulberg!CG16 -> 2 | J12: =Gulberg!CH16 -> 100% | K12: =COUNTA(Gulberg!I16:CD16)-COUNTIF(Gulberg!I16:CD16,"OFF") -> 72 | L12: =IF(G12+H12=0,"No Data",IF(G12/(G12+H12)>=0.9,"✅ Excellent",IF(G12/(G12+H12)>=0.75,"🟡 Good",IF(G12/(G12+H12)>=0.6,"🟠 Average","🔴 Low")))) -> ✅ Excellent
A13: 9 | B13: Gulberg | C13: =Gulberg!B17 -> Haseeb Ahmad | D13: =Gulberg!C17 -> '+923114322095 | E13: =IF(Gulberg!C17<>"",HYPERLINK("tel:"&SUBSTITUTE(SUBSTITUTE(Gulberg!C17,"+","+")," ",""),"📞"),"") -> 📞 | F13: =IF(Gulberg!C17<>"",HYPERLINK("https://wa.me/"&SUBSTITUTE(SUBSTITUTE(Gulberg!C17,"+","")," ",""),"💬"),"") -> 💬 | G13: =Gulberg!CE17 -> 13 | H13: =Gulberg!CF17 -> 3 | I13: =Gulberg!CG17 -> 2 | J13: =Gulberg!CH17 -> 81% | K13: =COUNTA(Gulberg!I17:CD17)-COUNTIF(Gulberg!I17:CD17,"OFF") -> 72 | L13: =IF(G13+H13=0,"No Data",IF(G13/(G13+H13)>=0.9,"✅ Excellent",IF(G13/(G13+H13)>=0.75,"🟡 Good",IF(G13/(G13+H13)>=0.6,"🟠 Average","🔴 Low")))) -> 🟡 Good
A14: 10 | B14: Gulberg | C14: =Gulberg!B18 -> Abu Hurairah | D14: =Gulberg!C18 | E14: =IF(Gulberg!C18<>"",HYPERLINK("tel:"&SUBSTITUTE(SUBSTITUTE(Gulberg!C18,"+","+")," ",""),"📞"),"") | F14: =IF(Gulberg!C18<>"",HYPERLINK("https://wa.me/"&SUBSTITUTE(SUBSTITUTE(Gulberg!C18,"+","")," ",""),"💬"),"") | G14: =Gulberg!CE18 -> 18 | H14: =Gulberg!CF18 -> 0 | I14: =Gulberg!CG18 -> 0 | J14: =Gulberg!CH18 -> 100% | K14: =COUNTA(Gulberg!I18:CD18)-COUNTIF(Gulberg!I18:CD18,"OFF") -> 72 | L14: =IF(G14+H14=0,"No Data",IF(G14/(G14+H14)>=0.9,"✅ Excellent",IF(G14/(G14+H14)>=0.75,"🟡 Good",IF(G14/(G14+H14)>=0.6,"🟠 Average","🔴 Low")))) -> ✅ Excellent
A15: 11 | B15: Gulberg | C15: =Gulberg!B19 -> Abdullah Saif | D15: =Gulberg!C19 -> '+923104362545 | E15: =IF(Gulberg!C19<>"",HYPERLINK("tel:"&SUBSTITUTE(SUBSTITUTE(Gulberg!C19,"+","+")," ",""),"📞"),"") -> 📞 | F15: =IF(Gulberg!C19<>"",HYPERLINK("https://wa.me/"&SUBSTITUTE(SUBSTITUTE(Gulberg!C19,"+","")," ",""),"💬"),"") -> 💬 | G15: =Gulberg!CE19 -> 8 | H15: =Gulberg!CF19 -> 5 | I15: =Gulberg!CG19 -> 5 | J15: =Gulberg!CH19 -> 62% | K15: =COUNTA(Gulberg!I19:CD19)-COUNTIF(Gulberg!I19:CD19,"OFF") -> 72 | L15: =IF(G15+H15=0,"No Data",IF(G15/(G15+H15)>=0.9,"✅ Excellent",IF(G15/(G15+H15)>=0.75,"🟡 Good",IF(G15/(G15+H15)>=0.6,"🟠 Average","🔴 Low")))) -> 🟠 Average
A16: 12 | B16: Gulberg | C16: =Gulberg!B20 -> Ameer Hamza | D16: =Gulberg!C20 -> +92 324 7197841 | E16: =IF(Gulberg!C20<>"",HYPERLINK("tel:"&SUBSTITUTE(SUBSTITUTE(Gulberg!C20,"+","+")," ",""),"📞"),"") -> 📞 | F16: =IF(Gulberg!C20<>"",HYPERLINK("https://wa.me/"&SUBSTITUTE(SUBSTITUTE(Gulberg!C20,"+","")," ",""),"💬"),"") -> 💬 | G16: =Gulberg!CE20 -> 8 | H16: =Gulberg!CF20 -> 1 | I16: =Gulberg!CG20 -> 1 | J16: =Gulberg!CH20 -> 89% | K16: =COUNTA(Gulberg!I20:CD20)-COUNTIF(Gulberg!I20:CD20,"OFF") -> 73 | L16: =IF(G16+H16=0,"No Data",IF(G16/(G16+H16)>=0.9,"✅ Excellent",IF(G16/(G16+H16)>=0.75,"🟡 Good",IF(G16/(G16+H16)>=0.6,"🟠 Average","🔴 Low")))) -> 🟡 Good
A17: =IF(Gulberg!B21<>"",13,"") -> 13 | B17: =IF(Gulberg!B21<>"","Gulberg","") -> Gulberg | C17: =IF(Gulberg!B21<>"",Gulberg!B21,"") -> Alman | D17: =IF(Gulberg!B21<>"",Gulberg!C21,"") -> +92 314 7364357 | E17: =IF(Gulberg!B21<>"",HYPERLINK("tel:"&SUBSTITUTE(SUBSTITUTE(Gulberg!C21,"+","+")," ",""),"📞"),"") -> 📞 | F17: =IF(Gulberg!B21<>"",HYPERLINK("https://wa.me/"&SUBSTITUTE(SUBSTITUTE(Gulberg!C21,"+","")," ",""),"💬"),"") -> 💬 | G17: =IF(Gulberg!B21<>"",Gulberg!CE21,"") -> 1 | H17: =IF(Gulberg!B21<>"",Gulberg!CF21,"") -> 1 | I17: =IF(Gulberg!B21<>"",Gulberg!CG21,"") -> 0 | J17: =IF(Gulberg!B21<>"",Gulberg!CH21,"") -> 50% | K17: =IF(Gulberg!B21<>"",COUNTA(Gulberg!I21:CD21)-COUNTIF(Gulberg!I21:CD21,"OFF"),"") -> 73 | L17: =IF(Gulberg!B21="","",IF(G17+H17=0,"No Data",IF(G17/(G17+H17)>=0.9,"✅ Excellent",IF(G17/(G17+H17)>=0.75,"🟡 Good",IF(G17/(G17+H17)>=0.6,"🟠 Average","🔴 Low"))))) -> 🔴 Low
A18: =IF(Gulberg!B22<>"",14,"") -> 14 | B18: =IF(Gulberg!B22<>"","Gulberg","") -> Gulberg | C18: =IF(Gulberg!B22<>"",Gulberg!B22,"") -> Suhaib | D18: =IF(Gulberg!B22<>"",Gulberg!C22,"") | E18: =IF(Gulberg!B22<>"",HYPERLINK("tel:"&SUBSTITUTE(SUBSTITUTE(Gulberg!C22,"+","+")," ",""),"📞"),"") -> 📞 | F18: =IF(Gulberg!B22<>"",HYPERLINK("https://wa.me/"&SUBSTITUTE(SUBSTITUTE(Gulberg!C22,"+","")," ",""),"💬"),"") -> 💬 | G18: =IF(Gulberg!B22<>"",Gulberg!CE22,"") -> 1 | H18: =IF(Gulberg!B22<>"",Gulberg!CF22,"") -> 1 | I18: =IF(Gulberg!B22<>"",Gulberg!CG22,"") -> 0 | J18: =IF(Gulberg!B22<>"",Gulberg!CH22,"") -> 50% | K18: =IF(Gulberg!B22<>"",COUNTA(Gulberg!I22:CD22)-COUNTIF(Gulberg!I22:CD22,"OFF"),"") -> 73 | L18: =IF(Gulberg!B22="","",IF(G18+H18=0,"No Data",IF(G18/(G18+H18)>=0.9,"✅ Excellent",IF(G18/(G18+H18)>=0.75,"🟡 Good",IF(G18/(G18+H18)>=0.6,"🟠 Average","🔴 Low"))))) -> 🔴 Low
A19: =IF(Gulberg!B23<>"",15,"") -> 15 | B19: =IF(Gulberg!B23<>"","Gulberg","") -> Gulberg | C19: =IF(Gulberg!B23<>"",Gulberg!B23,"") -> Nauman Imtiaz | D19: =IF(Gulberg!B23<>"",Gulberg!C23,"") -> +92 333 4115355 | E19: =IF(Gulberg!B23<>"",HYPERLINK("tel:"&SUBSTITUTE(SUBSTITUTE(Gulberg!C23,"+","+")," ",""),"📞"),"") -> 📞 | F19: =IF(Gulberg!B23<>"",HYPERLINK("https://wa.me/"&SUBSTITUTE(SUBSTITUTE(Gulberg!C23,"+","")," ",""),"💬"),"") -> 💬 | G19: =IF(Gulberg!B23<>"",Gulberg!CE23,"") -> 2 | H19: =IF(Gulberg!B23<>"",Gulberg!CF23,"") -> 0 | I19: =IF(Gulberg!B23<>"",Gulberg!CG23,"") -> 0 | J19: =IF(Gulberg!B23<>"",Gulberg!CH23,"") -> 100% | K19: =IF(Gulberg!B23<>"",COUNTA(Gulberg!I23:CD23)-COUNTIF(Gulberg!I23:CD23,"OFF"),"") -> 73 | L19: =IF(Gulberg!B23="","",IF(G19+H19=0,"No Data",IF(G19/(G19+H19)>=0.9,"✅ Excellent",IF(G19/(G19+H19)>=0.75,"🟡 Good",IF(G19/(G19+H19)>=0.6,"🟠 Average","🔴 Low"))))) -> ✅ Excellent
A21: ="▶ Gulshan Iqbal — "&SUMPRODUCT((LEN(C22:C31)>0)*1)&" Murabbis" -> ▶ Gulshan Iqbal — 9 Murabbis
A22: 13 | B22: Gulshan Iqbal | C22: =Gulshan_Iqbal!B9 -> Danish Qureshi | D22: =Gulshan_Iqbal!C9 | E22: =IF(Gulshan_Iqbal!C9<>"",HYPERLINK("tel:"&SUBSTITUTE(SUBSTITUTE(Gulshan_Iqbal!C9,"+","+")," ",""),"📞"),"") | F22: =IF(Gulshan_Iqbal!C9<>"",HYPERLINK("https://wa.me/"&SUBSTITUTE(SUBSTITUTE(Gulshan_Iqbal!C9,"+","")," ",""),"💬"),"") | G22: =Gulshan_Iqbal!CE9 -> 16 | H22: =Gulshan_Iqbal!CF9 -> 0 | I22: =Gulshan_Iqbal!CG9 -> 0 | J22: =Gulshan_Iqbal!CH9 -> 100% | K22: =COUNTA(Gulshan_Iqbal!I9:CD9)-COUNTIF(Gulshan_Iqbal!I9:CD9,"OFF") -> 72 | L22: =IF(G22+H22=0,"No Data",IF(G22/(G22+H22)>=0.9,"✅ Excellent",IF(G22/(G22+H22)>=0.75,"🟡 Good",IF(G22/(G22+H22)>=0.6,"🟠 Average","🔴 Low")))) -> ✅ Excellent
A23: 14 | B23: Gulshan Iqbal | C23: =Gulshan_Iqbal!B10 -> Faizan Ibrahim | D23: =Gulshan_Iqbal!C10 | E23: =IF(Gulshan_Iqbal!C10<>"",HYPERLINK("tel:"&SUBSTITUTE(SUBSTITUTE(Gulshan_Iqbal!C10,"+","+")," ",""),"📞"),"") | F23: =IF(Gulshan_Iqbal!C10<>"",HYPERLINK("https://wa.me/"&SUBSTITUTE(SUBSTITUTE(Gulshan_Iqbal!C10,"+","")," ",""),"💬"),"") | G23: =Gulshan_Iqbal!CE10 -> 15 | H23: =Gulshan_Iqbal!CF10 -> 0 | I23: =Gulshan_Iqbal!CG10 -> 1 | J23: =Gulshan_Iqbal!CH10 -> 100% | K23: =COUNTA(Gulshan_Iqbal!I10:CD10)-COUNTIF(Gulshan_Iqbal!I10:CD10,"OFF") -> 72 | L23: =IF(G23+H23=0,"No Data",IF(G23/(G23+H23)>=0.9,"✅ Excellent",IF(G23/(G23+H23)>=0.75,"🟡 Good",IF(G23/(G23+H23)>=0.6,"🟠 Average","🔴 Low")))) -> ✅ Excellent
A24: 15 | B24: Gulshan Iqbal | C24: =Gulshan_Iqbal!B11 -> Hamza Mehmood | D24: =Gulshan_Iqbal!C11 | E24: =IF(Gulshan_Iqbal!C11<>"",HYPERLINK("tel:"&SUBSTITUTE(SUBSTITUTE(Gulshan_Iqbal!C11,"+","+")," ",""),"📞"),"") | F24: =IF(Gulshan_Iqbal!C11<>"",HYPERLINK("https://wa.me/"&SUBSTITUTE(SUBSTITUTE(Gulshan_Iqbal!C11,"+","")," ",""),"💬"),"") | G24: =Gulshan_Iqbal!CE11 -> 16 | H24: =Gulshan_Iqbal!CF11 -> 0 | I24: =Gulshan_Iqbal!CG11 -> 0 | J24: =Gulshan_Iqbal!CH11 -> 100% | K24: =COUNTA(Gulshan_Iqbal!I11:CD11)-COUNTIF(Gulshan_Iqbal!I11:CD11,"OFF") -> 72 | L24: =IF(G24+H24=0,"No Data",IF(G24/(G24+H24)>=0.9,"✅ Excellent",IF(G24/(G24+H24)>=0.75,"🟡 Good",IF(G24/(G24+H24)>=0.6,"🟠 Average","🔴 Low")))) -> ✅ Excellent
A25: 16 | B25: Gulshan Iqbal | C25: =Gulshan_Iqbal!B12 -> Muhammad Hunain | D25: =Gulshan_Iqbal!C12 | E25: =IF(Gulshan_Iqbal!C12<>"",HYPERLINK("tel:"&SUBSTITUTE(SUBSTITUTE(Gulshan_Iqbal!C12,"+","+")," ",""),"📞"),"") | F25: =IF(Gulshan_Iqbal!C12<>"",HYPERLINK("https://wa.me/"&SUBSTITUTE(SUBSTITUTE(Gulshan_Iqbal!C12,"+","")," ",""),"💬"),"") | G25: =Gulshan_Iqbal!CE12 -> 14 | H25: =Gulshan_Iqbal!CF12 -> 0 | I25: =Gulshan_Iqbal!CG12 -> 0 | J25: =Gulshan_Iqbal!CH12 -> 100% | K25: =COUNTA(Gulshan_Iqbal!I12:CD12)-COUNTIF(Gulshan_Iqbal!I12:CD12,"OFF") -> 72 | L25: =IF(G25+H25=0,"No Data",IF(G25/(G25+H25)>=0.9,"✅ Excellent",IF(G25/(G25+H25)>=0.75,"🟡 Good",IF(G25/(G25+H25)>=0.6,"🟠 Average","🔴 Low")))) -> ✅ Excellent
A26: 17 | B26: Gulshan Iqbal | C26: =Gulshan_Iqbal!B13 -> Fayez | D26: =Gulshan_Iqbal!C13 | E26: =IF(Gulshan_Iqbal!C13<>"",HYPERLINK("tel:"&SUBSTITUTE(SUBSTITUTE(Gulshan_Iqbal!C13,"+","+")," ",""),"📞"),"") | F26: =IF(Gulshan_Iqbal!C13<>"",HYPERLINK("https://wa.me/"&SUBSTITUTE(SUBSTITUTE(Gulshan_Iqbal!C13,"+","")," ",""),"💬"),"") | G26: =Gulshan_Iqbal!CE13 -> 10 | H26: =Gulshan_Iqbal!CF13 -> 1 | I26: =Gulshan_Iqbal!CG13 -> 1 | J26: =Gulshan_Iqbal!CH13 -> 91% | K26: =COUNTA(Gulshan_Iqbal!I13:CD13)-COUNTIF(Gulshan_Iqbal!I13:CD13,"OFF") -> 72 | L26: =IF(G26+H26=0,"No Data",IF(G26/(G26+H26)>=0.9,"✅ Excellent",IF(G26/(G26+H26)>=0.75,"🟡 Good",IF(G26/(G26+H26)>=0.6,"🟠 Average","🔴 Low")))) -> ✅ Excellent
A27: 18 | B27: Gulshan Iqbal | C27: =Gulshan_Iqbal!B14 -> Muhammad Mateen | D27: =Gulshan_Iqbal!C14 | E27: =IF(Gulshan_Iqbal!C14<>"",HYPERLINK("tel:"&SUBSTITUTE(SUBSTITUTE(Gulshan_Iqbal!C14,"+","+")," ",""),"📞"),"") | F27: =IF(Gulshan_Iqbal!C14<>"",HYPERLINK("https://wa.me/"&SUBSTITUTE(SUBSTITUTE(Gulshan_Iqbal!C14,"+","")," ",""),"💬"),"") | G27: =Gulshan_Iqbal!CE14 -> 14 | H27: =Gulshan_Iqbal!CF14 -> 0 | I27: =Gulshan_Iqbal!CG14 -> 0 | J27: =Gulshan_Iqbal!CH14 -> 100% | K27: =COUNTA(Gulshan_Iqbal!I14:CD14)-COUNTIF(Gulshan_Iqbal!I14:CD14,"OFF") -> 72 | L27: =IF(G27+H27=0,"No Data",IF(G27/(G27+H27)>=0.9,"✅ Excellent",IF(G27/(G27+H27)>=0.75,"🟡 Good",IF(G27/(G27+H27)>=0.6,"🟠 Average","🔴 Low")))) -> ✅ Excellent
A28: 19 | B28: Gulshan Iqbal | C28: =Gulshan_Iqbal!B15 -> Faheem Badar | D28: =Gulshan_Iqbal!C15 | E28: =IF(Gulshan_Iqbal!C15<>"",HYPERLINK("tel:"&SUBSTITUTE(SUBSTITUTE(Gulshan_Iqbal!C15,"+","+")," ",""),"📞"),"") | F28: =IF(Gulshan_Iqbal!C15<>"",HYPERLINK("https://wa.me/"&SUBSTITUTE(SUBSTITUTE(Gulshan_Iqbal!C15,"+","")," ",""),"💬"),"") | G28: =Gulshan_Iqbal!CE15 -> 9 | H28: =Gulshan_Iqbal!CF15 -> 0 | I28: =Gulshan_Iqbal!CG15 -> 0 | J28: =Gulshan_Iqbal!CH15 -> 100% | K28: =COUNTA(Gulshan_Iqbal!I15:CD15)-COUNTIF(Gulshan_Iqbal!I15:CD15,"OFF") -> 73 | L28: =IF(G28+H28=0,"No Data",IF(G28/(G28+H28)>=0.9,"✅ Excellent",IF(G28/(G28+H28)>=0.75,"🟡 Good",IF(G28/(G28+H28)>=0.6,"🟠 Average","🔴 Low")))) -> ✅ Excellent
A29: =IF(Gulshan_Iqbal!B16<>"",8,"") -> 8 | B29: =IF(Gulshan_Iqbal!B16<>"","Gulshan Iqbal","") -> Gulshan Iqbal | C29: =IF(Gulshan_Iqbal!B16<>"",Gulshan_Iqbal!B16,"") -> Muhammad Musab | D29: =IF(Gulshan_Iqbal!B16<>"",Gulshan_Iqbal!C16,"") | E29: =IF(Gulshan_Iqbal!B16<>"",HYPERLINK("tel:"&SUBSTITUTE(SUBSTITUTE(Gulshan_Iqbal!C16,"+","+")," ",""),"📞"),"") -> 📞 | F29: =IF(Gulshan_Iqbal!B16<>"",HYPERLINK("https://wa.me/"&SUBSTITUTE(SUBSTITUTE(Gulshan_Iqbal!C16,"+","")," ",""),"💬"),"") -> 💬 | G29: =IF(Gulshan_Iqbal!B16<>"",Gulshan_Iqbal!CE16,"") -> 7 | H29: =IF(Gulshan_Iqbal!B16<>"",Gulshan_Iqbal!CF16,"") -> 2 | I29: =IF(Gulshan_Iqbal!B16<>"",Gulshan_Iqbal!CG16,"") -> 0 | J29: =IF(Gulshan_Iqbal!B16<>"",Gulshan_Iqbal!CH16,"") -> 78% | K29: =IF(Gulshan_Iqbal!B16<>"",COUNTA(Gulshan_Iqbal!I16:CD16)-COUNTIF(Gulshan_Iqbal!I16:CD16,"OFF"),"") -> 73 | L29: =IF(Gulshan_Iqbal!B16="","",IF(G29+H29=0,"No Data",IF(G29/(G29+H29)>=0.9,"✅ Excellent",IF(G29/(G29+H29)>=0.75,"🟡 Good",IF(G29/(G29+H29)>=0.6,"🟠 Average","🔴 Low"))))) -> 🟡 Good
A30: =IF(Gulshan_Iqbal!B17<>"",9,"") -> 9 | B30: =IF(Gulshan_Iqbal!B17<>"","Gulshan Iqbal","") -> Gulshan Iqbal | C30: =IF(Gulshan_Iqbal!B17<>"",Gulshan_Iqbal!B17,"") -> Muhammad Hammad | D30: =IF(Gulshan_Iqbal!B17<>"",Gulshan_Iqbal!C17,"") | E30: =IF(Gulshan_Iqbal!B17<>"",HYPERLINK("tel:"&SUBSTITUTE(SUBSTITUTE(Gulshan_Iqbal!C17,"+","+")," ",""),"📞"),"") -> 📞 | F30: =IF(Gulshan_Iqbal!B17<>"",HYPERLINK("https://wa.me/"&SUBSTITUTE(SUBSTITUTE(Gulshan_Iqbal!C17,"+","")," ",""),"💬"),"") -> 💬 | G30: =IF(Gulshan_Iqbal!B17<>"",Gulshan_Iqbal!CE17,"") -> 5 | H30: =IF(Gulshan_Iqbal!B17<>"",Gulshan_Iqbal!CF17,"") -> 4 | I30: =IF(Gulshan_Iqbal!B17<>"",Gulshan_Iqbal!CG17,"") -> 0 | J30: =IF(Gulshan_Iqbal!B17<>"",Gulshan_Iqbal!CH17,"") -> 56% | K30: =IF(Gulshan_Iqbal!B17<>"",COUNTA(Gulshan_Iqbal!I17:CD17)-COUNTIF(Gulshan_Iqbal!I17:CD17,"OFF"),"") -> 73 | L30: =IF(Gulshan_Iqbal!B17="","",IF(G30+H30=0,"No Data",IF(G30/(G30+H30)>=0.9,"✅ Excellent",IF(G30/(G30+H30)>=0.75,"🟡 Good",IF(G30/(G30+H30)>=0.6,"🟠 Average","🔴 Low"))))) -> 🔴 Low
A31: =IF(Gulshan_Iqbal!B18<>"",10,"") | B31: =IF(Gulshan_Iqbal!B18<>"","Gulshan Iqbal","") | C31: =IF(Gulshan_Iqbal!B18<>"",Gulshan_Iqbal!B18,"") | D31: =IF(Gulshan_Iqbal!B18<>"",Gulshan_Iqbal!C18,"") | E31: =IF(Gulshan_Iqbal!B18<>"",HYPERLINK("tel:"&SUBSTITUTE(SUBSTITUTE(Gulshan_Iqbal!C18,"+","+")," ",""),"📞"),"") | F31: =IF(Gulshan_Iqbal!B18<>"",HYPERLINK("https://wa.me/"&SUBSTITUTE(SUBSTITUTE(Gulshan_Iqbal!C18,"+","")," ",""),"💬"),"") | G31: =IF(Gulshan_Iqbal!B18<>"",Gulshan_Iqbal!CE18,"") | H31: =IF(Gulshan_Iqbal!B18<>"",Gulshan_Iqbal!CF18,"") | I31: =IF(Gulshan_Iqbal!B18<>"",Gulshan_Iqbal!CG18,"") | J31: =IF(Gulshan_Iqbal!B18<>"",Gulshan_Iqbal!CH18,"") | K31: =IF(Gulshan_Iqbal!B18<>"",COUNTA(Gulshan_Iqbal!I18:CD18)-COUNTIF(Gulshan_Iqbal!I18:CD18,"OFF"),"") | L31: =IF(Gulshan_Iqbal!B18="","",IF(G31+H31=0,"No Data",IF(G31/(G31+H31)>=0.9,"✅ Excellent",IF(G31/(G31+H31)>=0.75,"🟡 Good",IF(G31/(G31+H31)>=0.6,"🟠 Average","🔴 Low")))))
A33: ="▶ Griffin — "&SUMPRODUCT((LEN(C34:C38)>0)*1)&" Murabbis" -> ▶ Griffin — 3 Murabbis
A34: 20 | B34: Griffin | C34: =Griffin!B9 -> Fahad bhai | D34: =Griffin!C9 | E34: =IF(Griffin!C9<>"",HYPERLINK("tel:"&SUBSTITUTE(SUBSTITUTE(Griffin!C9,"+","+")," ",""),"📞"),"") | F34: =IF(Griffin!C9<>"",HYPERLINK("https://wa.me/"&SUBSTITUTE(SUBSTITUTE(Griffin!C9,"+","")," ",""),"💬"),"") | G34: =Griffin!CE9 -> 18 | H34: =Griffin!CF9 -> 0 | I34: =Griffin!CG9 -> 0 | J34: =Griffin!CH9 -> 100% | K34: =COUNTA(Griffin!I9:CD9)-COUNTIF(Griffin!I9:CD9,"OFF") -> 72 | L34: =IF(G34+H34=0,"No Data",IF(G34/(G34+H34)>=0.9,"✅ Excellent",IF(G34/(G34+H34)>=0.75,"🟡 Good",IF(G34/(G34+H34)>=0.6,"🟠 Average","🔴 Low")))) -> ✅ Excellent
A35: 21 | B35: Griffin | C35: =Griffin!B10 -> Bilal bhai | D35: =Griffin!C10 | E35: =IF(Griffin!C10<>"",HYPERLINK("tel:"&SUBSTITUTE(SUBSTITUTE(Griffin!C10,"+","+")," ",""),"📞"),"") | F35: =IF(Griffin!C10<>"",HYPERLINK("https://wa.me/"&SUBSTITUTE(SUBSTITUTE(Griffin!C10,"+","")," ",""),"💬"),"") | G35: =Griffin!CE10 -> 14 | H35: =Griffin!CF10 -> 0 | I35: =Griffin!CG10 -> 4 | J35: =Griffin!CH10 -> 100% | K35: =COUNTA(Griffin!I10:CD10)-COUNTIF(Griffin!I10:CD10,"OFF") -> 72 | L35: =IF(G35+H35=0,"No Data",IF(G35/(G35+H35)>=0.9,"✅ Excellent",IF(G35/(G35+H35)>=0.75,"🟡 Good",IF(G35/(G35+H35)>=0.6,"🟠 Average","🔴 Low")))) -> ✅ Excellent
A36: =IF(Griffin!B11<>"",3,"") -> 3 | B36: =IF(Griffin!B11<>"","Griffin","") -> Griffin | C36: =IF(Griffin!B11<>"",Griffin!B11,"") -> Talha Afridi Bhai | D36: =IF(Griffin!B11<>"",Griffin!C11,"") | E36: =IF(Griffin!B11<>"",HYPERLINK("tel:"&SUBSTITUTE(SUBSTITUTE(Griffin!C11,"+","+")," ",""),"📞"),"") -> 📞 | F36: =IF(Griffin!B11<>"",HYPERLINK("https://wa.me/"&SUBSTITUTE(SUBSTITUTE(Griffin!C11,"+","")," ",""),"💬"),"") -> 💬 | G36: =IF(Griffin!B11<>"",Griffin!CE11,"") -> 4 | H36: =IF(Griffin!B11<>"",Griffin!CF11,"") -> 0 | I36: =IF(Griffin!B11<>"",Griffin!CG11,"") -> 0 | J36: =IF(Griffin!B11<>"",Griffin!CH11,"") -> 100% | K36: =IF(Griffin!B11<>"",COUNTA(Griffin!I11:CD11)-COUNTIF(Griffin!I11:CD11,"OFF"),"") -> 73 | L36: =IF(Griffin!B11="","",IF(G36+H36=0,"No Data",IF(G36/(G36+H36)>=0.9,"✅ Excellent",IF(G36/(G36+H36)>=0.75,"🟡 Good",IF(G36/(G36+H36)>=0.6,"🟠 Average","🔴 Low"))))) -> ✅ Excellent
A37: =IF(Griffin!B12<>"",4,"") | B37: =IF(Griffin!B12<>"","Griffin","") | C37: =IF(Griffin!B12<>"",Griffin!B12,"") | D37: =IF(Griffin!B12<>"",Griffin!C12,"") | E37: =IF(Griffin!B12<>"",HYPERLINK("tel:"&SUBSTITUTE(SUBSTITUTE(Griffin!C12,"+","+")," ",""),"📞"),"") | F37: =IF(Griffin!B12<>"",HYPERLINK("https://wa.me/"&SUBSTITUTE(SUBSTITUTE(Griffin!C12,"+","")," ",""),"💬"),"") | G37: =IF(Griffin!B12<>"",Griffin!CE12,"") | H37: =IF(Griffin!B12<>"",Griffin!CF12,"") | I37: =IF(Griffin!B12<>"",Griffin!CG12,"") | J37: =IF(Griffin!B12<>"",Griffin!CH12,"") | K37: =IF(Griffin!B12<>"",COUNTA(Griffin!I12:CD12)-COUNTIF(Griffin!I12:CD12,"OFF"),"") | L37: =IF(Griffin!B12="","",IF(G37+H37=0,"No Data",IF(G37/(G37+H37)>=0.9,"✅ Excellent",IF(G37/(G37+H37)>=0.75,"🟡 Good",IF(G37/(G37+H37)>=0.6,"🟠 Average","🔴 Low")))))
A38: =IF(Griffin!B13<>"",5,"") | B38: =IF(Griffin!B13<>"","Griffin","") | C38: =IF(Griffin!B13<>"",Griffin!B13,"") | D38: =IF(Griffin!B13<>"",Griffin!C13,"") | E38: =IF(Griffin!B13<>"",HYPERLINK("tel:"&SUBSTITUTE(SUBSTITUTE(Griffin!C13,"+","+")," ",""),"📞"),"") | F38: =IF(Griffin!B13<>"",HYPERLINK("https://wa.me/"&SUBSTITUTE(SUBSTITUTE(Griffin!C13,"+","")," ",""),"💬"),"") | G38: =IF(Griffin!B13<>"",Griffin!CE13,"") | H38: =IF(Griffin!B13<>"",Griffin!CF13,"") | I38: =IF(Griffin!B13<>"",Griffin!CG13,"") | J38: =IF(Griffin!B13<>"",Griffin!CH13,"") | K38: =IF(Griffin!B13<>"",COUNTA(Griffin!I13:CD13)-COUNTIF(Griffin!I13:CD13,"OFF"),"") | L38: =IF(Griffin!B13="","",IF(G38+H38=0,"No Data",IF(G38/(G38+H38)>=0.9,"✅ Excellent",IF(G38/(G38+H38)>=0.75,"🟡 Good",IF(G38/(G38+H38)>=0.6,"🟠 Average","🔴 Low")))))
A40: ="▶ Johar Town — "&SUMPRODUCT((LEN(C41:C50)>0)*1)&" Murabbis" -> ▶ Johar Town — 10 Murabbis
A41: 22 | B41: Johar Town | C41: =Johar_Town!B9 -> Hamza Badar | D41: =Johar_Town!C9 -> '+923228498237 | E41: =IF(Johar_Town!C9<>"",HYPERLINK("tel:"&SUBSTITUTE(SUBSTITUTE(Johar_Town!C9,"+","+")," ",""),"📞"),"") -> 📞 | F41: =IF(Johar_Town!C9<>"",HYPERLINK("https://wa.me/"&SUBSTITUTE(SUBSTITUTE(Johar_Town!C9,"+","")," ",""),"💬"),"") -> 💬 | G41: =Johar_Town!CE9 -> 16 | H41: =Johar_Town!CF9 -> 0 | I41: =Johar_Town!CG9 -> 2 | J41: =Johar_Town!CH9 -> 100% | K41: =COUNTA(Johar_Town!I9:CD9)-COUNTIF(Johar_Town!I9:CD9,"OFF") -> 72 | L41: =IF(G41+H41=0,"No Data",IF(G41/(G41+H41)>=0.9,"✅ Excellent",IF(G41/(G41+H41)>=0.75,"🟡 Good",IF(G41/(G41+H41)>=0.6,"🟠 Average","🔴 Low")))) -> ✅ Excellent
A42: 23 | B42: Johar Town | C42: =Johar_Town!B10 -> Hassan Basil | D42: =Johar_Town!C10 -> '+923331047726 | E42: =IF(Johar_Town!C10<>"",HYPERLINK("tel:"&SUBSTITUTE(SUBSTITUTE(Johar_Town!C10,"+","+")," ",""),"📞"),"") -> 📞 | F42: =IF(Johar_Town!C10<>"",HYPERLINK("https://wa.me/"&SUBSTITUTE(SUBSTITUTE(Johar_Town!C10,"+","")," ",""),"💬"),"") -> 💬 | G42: =Johar_Town!CE10 -> 1 | H42: =Johar_Town!CF10 -> 11 | I42: =Johar_Town!CG10 -> 6 | J42: =Johar_Town!CH10 -> 8% | K42: =COUNTA(Johar_Town!I10:CD10)-COUNTIF(Johar_Town!I10:CD10,"OFF") -> 72 | L42: =IF(G42+H42=0,"No Data",IF(G42/(G42+H42)>=0.9,"✅ Excellent",IF(G42/(G42+H42)>=0.75,"🟡 Good",IF(G42/(G42+H42)>=0.6,"🟠 Average","🔴 Low")))) -> 🔴 Low
A43: 24 | B43: Johar Town | C43: =Johar_Town!B11 -> Abdullah Rizwan | D43: =Johar_Town!C11 -> '+923254419155 | E43: =IF(Johar_Town!C11<>"",HYPERLINK("tel:"&SUBSTITUTE(SUBSTITUTE(Johar_Town!C11,"+","+")," ",""),"📞"),"") -> 📞 | F43: =IF(Johar_Town!C11<>"",HYPERLINK("https://wa.me/"&SUBSTITUTE(SUBSTITUTE(Johar_Town!C11,"+","")," ",""),"💬"),"") -> 💬 | G43: =Johar_Town!CE11 -> 4 | H43: =Johar_Town!CF11 -> 11 | I43: =Johar_Town!CG11 -> 3 | J43: =Johar_Town!CH11 -> 27% | K43: =COUNTA(Johar_Town!I11:CD11)-COUNTIF(Johar_Town!I11:CD11,"OFF") -> 72 | L43: =IF(G43+H43=0,"No Data",IF(G43/(G43+H43)>=0.9,"✅ Excellent",IF(G43/(G43+H43)>=0.75,"🟡 Good",IF(G43/(G43+H43)>=0.6,"🟠 Average","🔴 Low")))) -> 🔴 Low
...

Sheet 📊 Class Stats
A1: 📊 SHABAB BATCH 4 – CLASS-WISE STATISTICS | Students Only | 2026-2027
D2: Gulberg | I2: Gulshan Iqbal | N2: Griffin | S2: Johar Town | X2: Gulshan Ravi | AC2: State Life | AH2: 🌍 TOTAL (All Parks)
A3: # | B3: Date | C3: Day | D3: P | E3: A | F3: L | G3: Late | H3: % | I3: P | J3: A | K3: L | L3: Late | M3: % | N3: P | O3: A | P3: L | Q3: Late | R3: % | S3: P | T3: A | U3: L | V3: Late | W3: % | X3: P | Y3: A | Z3: L | AA3: Late | AB3: % | AC3: P | AD3: A | AE3: L | AF3: Late | AG3: % | AH3: Total P | AI3: Total A | AJ3: Total L | AK3: % Haazri
A4: 1 | B4: 23 May 2026 | C4: Saturday | D4: =COUNTIFS(Gulberg!B26:B149,"<>",Gulberg!I26:I149,"Present") -> 18 | E4: =COUNTIFS(Gulberg!B26:B149,"<>",Gulberg!I26:I149,"Absent") -> 26 | F4: =COUNTIFS(Gulberg!B26:B149,"<>",Gulberg!I26:I149,"Leave") -> 1 | G4: =COUNTIFS(Gulberg!B26:B149,"<>",Gulberg!I26:I149,"Late") -> 0 | H4: =IF(D4+E4+G4=0,"-",TEXT((D4+G4)/(D4+E4+G4),"0%")) -> 41% | I4: =COUNTIFS(Gulshan_Iqbal!B21:B150,"<>",Gulshan_Iqbal!I21:I150,"Present") -> 13 | J4: =COUNTIFS(Gulshan_Iqbal!B21:B150,"<>",Gulshan_Iqbal!I21:I150,"Absent") -> 27 | K4: =COUNTIFS(Gulshan_Iqbal!B21:B150,"<>",Gulshan_Iqbal!I21:I150,"Leave") -> 0 | L4: =COUNTIFS(Gulshan_Iqbal!B21:B150,"<>",Gulshan_Iqbal!I21:I150,"Late") -> 0 | M4: =IF(I4+J4+L4=0,"-",TEXT((I4+L4)/(I4+J4+L4),"0%")) -> 33% | N4: =COUNTIFS(Griffin!B16:B152,"<>",Griffin!I16:I152,"Present") -> 10 | O4: =COUNTIFS(Griffin!B16:B152,"<>",Griffin!I16:I152,"Absent") -> 6 | P4: =COUNTIFS(Griffin!B16:B152,"<>",Griffin!I16:I152,"Leave") -> 0 | Q4: =COUNTIFS(Griffin!B16:B152,"<>",Griffin!I16:I152,"Late") -> 8 | R4: =IF(N4+O4+Q4=0,"-",TEXT((N4+Q4)/(N4+O4+Q4),"0%")) -> 75% | S4: =COUNTIFS(Johar_Town!B21:B164,"<>",Johar_Town!I21:I164,"Present") -> 0 | T4: =COUNTIFS(Johar_Town!B21:B164,"<>",Johar_Town!I21:I164,"Absent") -> 13 | U4: =COUNTIFS(Johar_Town!B21:B164,"<>",Johar_Town!I21:I164,"Leave") -> 1 | V4: =COUNTIFS(Johar_Town!B21:B164,"<>",Johar_Town!I21:I164,"Late") -> 14 | W4: =IF(S4+T4+V4=0,"-",TEXT((S4+V4)/(S4+T4+V4),"0%")) -> 52% | X4: =COUNTIFS(Gulshan_Ravi!B23:B150,"<>",Gulshan_Ravi!I23:I150,"Present") -> 13 | Y4: =COUNTIFS(Gulshan_Ravi!B23:B150,"<>",Gulshan_Ravi!I23:I150,"Absent") -> 11 | Z4: =COUNTIFS(Gulshan_Ravi!B23:B150,"<>",Gulshan_Ravi!I23:I150,"Leave") -> 0 | AA4: =COUNTIFS(Gulshan_Ravi!B23:B150,"<>",Gulshan_Ravi!I23:I150,"Late") -> 0 | AB4: =IF(X4+Y4+AA4=0,"-",TEXT((X4+AA4)/(X4+Y4+AA4),"0%")) -> 54% | AC4: =COUNTIFS(State_Life!B18:B150,"<>",State_Life!I18:I150,"Present") -> 8 | AD4: =COUNTIFS(State_Life!B18:B150,"<>",State_Life!I18:I150,"Absent") -> 5 | AE4: =COUNTIFS(State_Life!B18:B150,"<>",State_Life!I18:I150,"Leave") -> 0 | AF4: =COUNTIFS(State_Life!B18:B150,"<>",State_Life!I18:I150,"Late") -> 3 | AG4: =IF(AC4+AD4+AF4=0,"-",TEXT((AC4+AF4)/(AC4+AD4+AF4),"0%")) -> 69% | AH4: =D4+I4+N4+S4+X4+AC4 -> 62 | AI4: =E4+J4+O4+T4+Y4+AD4 -> 88 | AJ4: =F4+K4+P4+U4+Z4+AE4 -> 2 | AK4: =IF(AH4+AI4=0,"-",TEXT((AH4+(G4+L4+Q4+V4+AA4+AF4))/((D4+I4+N4+S4+X4+AC4)+(G4+L4+Q4+V4+AA4+AF4)+(E4+J4+O4+T4+Y4+AD4)),"0%")) -> 50%
A5: 2 | B5: 24 May 2026 | C5: Sunday | D5: =COUNTIFS(Gulberg!B26:B149,"<>",Gulberg!J26:J149,"Present") -> 25 | E5: =COUNTIFS(Gulberg!B26:B149,"<>",Gulberg!J26:J149,"Absent") -> 20 | F5: =COUNTIFS(Gulberg!B26:B149,"<>",Gulberg!J26:J149,"Leave") -> 0 | G5: =COUNTIFS(Gulberg!B26:B149,"<>",Gulberg!J26:J149,"Late") -> 0 | H5: =IF(D5+E5+G5=0,"-",TEXT((D5+G5)/(D5+E5+G5),"0%")) -> 56% | I5: =COUNTIFS(Gulshan_Iqbal!B21:B150,"<>",Gulshan_Iqbal!J21:J150,"Present") -> 14 | J5: =COUNTIFS(Gulshan_Iqbal!B21:B150,"<>",Gulshan_Iqbal!J21:J150,"Absent") -> 22 | K5: =COUNTIFS(Gulshan_Iqbal!B21:B150,"<>",Gulshan_Iqbal!J21:J150,"Leave") -> 2 | L5: =COUNTIFS(Gulshan_Iqbal!B21:B150,"<>",Gulshan_Iqbal!J21:J150,"Late") -> 2 | M5: =IF(I5+J5+L5=0,"-",TEXT((I5+L5)/(I5+J5+L5),"0%")) -> 42% | N5: =COUNTIFS(Griffin!B16:B152,"<>",Griffin!J16:J152,"Present") -> 12 | O5: =COUNTIFS(Griffin!B16:B152,"<>",Griffin!J16:J152,"Absent") -> 14 | P5: =COUNTIFS(Griffin!B16:B152,"<>",Griffin!J16:J152,"Leave") -> 0 | Q5: =COUNTIFS(Griffin!B16:B152,"<>",Griffin!J16:J152,"Late") -> 0 | R5: =IF(N5+O5+Q5=0,"-",TEXT((N5+Q5)/(N5+O5+Q5),"0%")) -> 46% | S5: =COUNTIFS(Johar_Town!B21:B164,"<>",Johar_Town!J21:J164,"Present") -> 0 | T5: =COUNTIFS(Johar_Town!B21:B164,"<>",Johar_Town!J21:J164,"Absent") -> 10 | U5: =COUNTIFS(Johar_Town!B21:B164,"<>",Johar_Town!J21:J164,"Leave") -> 2 | V5: =COUNTIFS(Johar_Town!B21:B164,"<>",Johar_Town!J21:J164,"Late") -> 18 | W5: =IF(S5+T5+V5=0,"-",TEXT((S5+V5)/(S5+T5+V5),"0%")) -> 64% | X5: =COUNTIFS(Gulshan_Ravi!B23:B150,"<>",Gulshan_Ravi!J23:J150,"Present") -> 2 | Y5: =COUNTIFS(Gulshan_Ravi!B23:B150,"<>",Gulshan_Ravi!J23:J150,"Absent") -> 13 | Z5: =COUNTIFS(Gulshan_Ravi!B23:B150,"<>",Gulshan_Ravi!J23:J150,"Leave") -> 0 | AA5: =COUNTIFS(Gulshan_Ravi!B23:B150,"<>",Gulshan_Ravi!J23:J150,"Late") -> 9 | AB5: =IF(X5+Y5+AA5=0,"-",TEXT((X5+AA5)/(X5+Y5+AA5),"0%")) -> 46% | AC5: =COUNTIFS(State_Life!B18:B150,"<>",State_Life!J18:J150,"Present") -> 8 | AD5: =COUNTIFS(State_Life!B18:B150,"<>",State_Life!J18:J150,"Absent") -> 4 | AE5: =COUNTIFS(State_Life!B18:B150,"<>",State_Life!J18:J150,"Leave") -> 1 | AF5: =COUNTIFS(State_Life!B18:B150,"<>",State_Life!J18:J150,"Late") -> 3 | AG5: =IF(AC5+AD5+AF5=0,"-",TEXT((AC5+AF5)/(AC5+AD5+AF5),"0%")) -> 73% | AH5: =D5+I5+N5+S5+X5+AC5 -> 61 | AI5: =E5+J5+O5+T5+Y5+AD5 -> 83 | AJ5: =F5+K5+P5+U5+Z5+AE5 -> 5 | AK5: =IF(AH5+AI5=0,"-",TEXT((AH5+(G5+L5+Q5+V5+AA5+AF5))/((D5+I5+N5+S5+X5+AC5)+(G5+L5+Q5+V5+AA5+AF5)+(E5+J5+O5+T5+Y5+AD5)),"0%")) -> 53%
A6: 3 | B6: 30 May 2026 | C6: Saturday | D6: =COUNTIFS(Gulberg!B26:B149,"<>",Gulberg!K26:K149,"Present") -> 0 | E6: =COUNTIFS(Gulberg!B26:B149,"<>",Gulberg!K26:K149,"Absent") -> 0 | F6: =COUNTIFS(Gulberg!B26:B149,"<>",Gulberg!K26:K149,"Leave") -> 0 | G6: =COUNTIFS(Gulberg!B26:B149,"<>",Gulberg!K26:K149,"Late") -> 0 | H6: =IF(D6+E6+G6=0,"-",TEXT((D6+G6)/(D6+E6+G6),"0%")) -> - | I6: =COUNTIFS(Gulshan_Iqbal!B21:B150,"<>",Gulshan_Iqbal!K21:K150,"Present") -> 0 | J6: =COUNTIFS(Gulshan_Iqbal!B21:B150,"<>",Gulshan_Iqbal!K21:K150,"Absent") -> 0 | K6: =COUNTIFS(Gulshan_Iqbal!B21:B150,"<>",Gulshan_Iqbal!K21:K150,"Leave") -> 0 | L6: =COUNTIFS(Gulshan_Iqbal!B21:B150,"<>",Gulshan_Iqbal!K21:K150,"Late") -> 0 | M6: =IF(I6+J6+L6=0,"-",TEXT((I6+L6)/(I6+J6+L6),"0%")) -> - | N6: =COUNTIFS(Griffin!B16:B152,"<>",Griffin!K16:K152,"Present") -> 0 | O6: =COUNTIFS(Griffin!B16:B152,"<>",Griffin!K16:K152,"Absent") -> 0 | P6: =COUNTIFS(Griffin!B16:B152,"<>",Griffin!K16:K152,"Leave") -> 0 | Q6: =COUNTIFS(Griffin!B16:B152,"<>",Griffin!K16:K152,"Late") -> 0 | R6: =IF(N6+O6+Q6=0,"-",TEXT((N6+Q6)/(N6+O6+Q6),"0%")) -> - | S6: =COUNTIFS(Johar_Town!B21:B164,"<>",Johar_Town!K21:K164,"Present") -> 0 | T6: =COUNTIFS(Johar_Town!B21:B164,"<>",Johar_Town!K21:K164,"Absent") -> 0 | U6: =COUNTIFS(Johar_Town!B21:B164,"<>",Johar_Town!K21:K164,"Leave") -> 0 | V6: =COUNTIFS(Johar_Town!B21:B164,"<>",Johar_Town!K21:K164,"Late") -> 0 | W6: =IF(S6+T6+V6=0,"-",TEXT((S6+V6)/(S6+T6+V6),"0%")) -> - | X6: =COUNTIFS(Gulshan_Ravi!B23:B150,"<>",Gulshan_Ravi!K23:K150,"Present") -> 0 | Y6: =COUNTIFS(Gulshan_Ravi!B23:B150,"<>",Gulshan_Ravi!K23:K150,"Absent") -> 0 | Z6: =COUNTIFS(Gulshan_Ravi!B23:B150,"<>",Gulshan_Ravi!K23:K150,"Leave") -> 0 | AA6: =COUNTIFS(Gulshan_Ravi!B23:B150,"<>",Gulshan_Ravi!K23:K150,"Late") -> 0 | AB6: =IF(X6+Y6+AA6=0,"-",TEXT((X6+AA6)/(X6+Y6+AA6),"0%")) -> - | AC6: =COUNTIFS(State_Life!B18:B150,"<>",State_Life!K18:K150,"Present") -> 0 | AD6: =COUNTIFS(State_Life!B18:B150,"<>",State_Life!K18:K150,"Absent") -> 0 | AE6: =COUNTIFS(State_Life!B18:B150,"<>",State_Life!K18:K150,"Leave") -> 0 | AF6: =COUNTIFS(State_Life!B18:B150,"<>",State_Life!K18:K150,"Late") -> 0 | AG6: =IF(AC6+AD6+AF6=0,"-",TEXT((AC6+AF6)/(AC6+AD6+AF6),"0%")) -> - | AH6: =D6+I6+N6+S6+X6+AC6 -> 0 | AI6: =E6+J6+O6+T6+Y6+AD6 -> 0 | AJ6: =F6+K6+P6+U6+Z6+AE6 -> 0 | AK6: =IF(AH6+AI6=0,"-",TEXT((AH6+(G6+L6+Q6+V6+AA6+AF6))/((D6+I6+N6+S6+X6+AC6)+(G6+L6+Q6+V6+AA6+AF6)+(E6+J6+O6+T6+Y6+AD6)),"0%")) -> -
A7: 4 | B7: 31 May 2026 | C7: Sunday | D7: =COUNTIFS(Gulberg!B26:B149,"<>",Gulberg!L26:L149,"Present") -> 24 | E7: =COUNTIFS(Gulberg!B26:B149,"<>",Gulberg!L26:L149,"Absent") -> 17 | F7: =COUNTIFS(Gulberg!B26:B149,"<>",Gulberg!L26:L149,"Leave") -> 6 | G7: =COUNTIFS(Gulberg!B26:B149,"<>",Gulberg!L26:L149,"Late") -> 0 | H7: =IF(D7+E7+G7=0,"-",TEXT((D7+G7)/(D7+E7+G7),"0%")) -> 59% | I7: =COUNTIFS(Gulshan_Iqbal!B21:B150,"<>",Gulshan_Iqbal!L21:L150,"Present") -> 12 | J7: =COUNTIFS(Gulshan_Iqbal!B21:B150,"<>",Gulshan_Iqbal!L21:L150,"Absent") -> 13 | K7: =COUNTIFS(Gulshan_Iqbal!B21:B150,"<>",Gulshan_Iqbal!L21:L150,"Leave") -> 7 | L7: =COUNTIFS(Gulshan_Iqbal!B21:B150,"<>",Gulshan_Iqbal!L21:L150,"Late") -> 8 | M7: =IF(I7+J7+L7=0,"-",TEXT((I7+L7)/(I7+J7+L7),"0%")) -> 61% | N7: =COUNTIFS(Griffin!B16:B152,"<>",Griffin!L16:L152,"Present") -> 0 | O7: =COUNTIFS(Griffin!B16:B152,"<>",Griffin!L16:L152,"Absent") -> 12 | P7: =COUNTIFS(Griffin!B16:B152,"<>",Griffin!L16:L152,"Leave") -> 1 | Q7: =COUNTIFS(Griffin!B16:B152,"<>",Griffin!L16:L152,"Late") -> 13 | R7: =IF(N7+O7+Q7=0,"-",TEXT((N7+Q7)/(N7+O7+Q7),"0%")) -> 52% | S7: =COUNTIFS(Johar_Town!B21:B164,"<>",Johar_Town!L21:L164,"Present") -> 2 | T7: =COUNTIFS(Johar_Town!B21:B164,"<>",Johar_Town!L21:L164,"Absent") -> 16 | U7: =COUNTIFS(Johar_Town!B21:B164,"<>",Johar_Town!L21:L164,"Leave") -> 5 | V7: =COUNTIFS(Johar_Town!B21:B164,"<>",Johar_Town!L21:L164,"Late") -> 7 | W7: =IF(S7+T7+V7=0,"-",TEXT((S7+V7)/(S7+T7+V7),"0%")) -> 36% | X7: =COUNTIFS(Gulshan_Ravi!B23:B150,"<>",Gulshan_Ravi!L23:L150,"Present") -> 5 | Y7: =COUNTIFS(Gulshan_Ravi!B23:B150,"<>",Gulshan_Ravi!L23:L150,"Absent") -> 8 | Z7: =COUNTIFS(Gulshan_Ravi!B23:B150,"<>",Gulshan_Ravi!L23:L150,"Leave") -> 2 | AA7: =COUNTIFS(Gulshan_Ravi!B23:B150,"<>",Gulshan_Ravi!L23:L150,"Late") -> 9 | AB7: =IF(X7+Y7+AA7=0,"-",TEXT((X7+AA7)/(X7+Y7+AA7),"0%")) -> 64% | AC7: =COUNTIFS(State_Life!B18:B150,"<>",State_Life!L18:L150,"Present") -> 6 | AD7: =COUNTIFS(State_Life!B18:B150,"<>",State_Life!L18:L150,"Absent") -> 7 | AE7: =COUNTIFS(State_Life!B18:B150,"<>",State_Life!L18:L150,"Leave") -> 0 | AF7: =COUNTIFS(State_Life!B18:B150,"<>",State_Life!L18:L150,"Late") -> 3 | AG7: =IF(AC7+AD7+AF7=0,"-",TEXT((AC7+AF7)/(AC7+AD7+AF7),"0%")) -> 56% | AH7: =D7+I7+N7+S7+X7+AC7 -> 49 | AI7: =E7+J7+O7+T7+Y7+AD7 -> 73 | AJ7: =F7+K7+P7+U7+Z7+AE7 -> 21 | AK7: =IF(AH7+AI7=0,"-",TEXT((AH7+(G7+L7+Q7+V7+AA7+AF7))/((D7+I7+N7+S7+X7+AC7)+(G7+L7+Q7+V7+AA7+AF7)+(E7+J7+O7+T7+Y7+AD7)),"0%")) -> 55%
A8: 5 | B8: 06 Jun 2026 | C8: Saturday | D8: =COUNTIFS(Gulberg!B26:B149,"<>",Gulberg!M26:M149,"Present") -> 9 | E8: =COUNTIFS(Gulberg!B26:B149,"<>",Gulberg!M26:M149,"Absent") -> 17 | F8: =COUNTIFS(Gulberg!B26:B149,"<>",Gulberg!M26:M149,"Leave") -> 6 | G8: =COUNTIFS(Gulberg!B26:B149,"<>",Gulberg!M26:M149,"Late") -> 15 | H8: =IF(D8+E8+G8=0,"-",TEXT((D8+G8)/(D8+E8+G8),"0%")) -> 59% | I8: =COUNTIFS(Gulshan_Iqbal!B21:B150,"<>",Gulshan_Iqbal!M21:M150,"Present") -> 11 | J8: =COUNTIFS(Gulshan_Iqbal!B21:B150,"<>",Gulshan_Iqbal!M21:M150,"Absent") -> 20 | K8: =COUNTIFS(Gulshan_Iqbal!B21:B150,"<>",Gulshan_Iqbal!M21:M150,"Leave") -> 4 | L8: =COUNTIFS(Gulshan_Iqbal!B21:B150,"<>",Gulshan_Iqbal!M21:M150,"Late") -> 5 | M8: =IF(I8+J8+L8=0,"-",TEXT((I8+L8)/(I8+J8+L8),"0%")) -> 44% | N8: =COUNTIFS(Griffin!B16:B152,"<>",Griffin!M16:M152,"Present") -> 13 | O8: =COUNTIFS(Griffin!B16:B152,"<>",Griffin!M16:M152,"Absent") -> 12 | P8: =COUNTIFS(Griffin!B16:B152,"<>",Griffin!M16:M152,"Leave") -> 0 | Q8: =COUNTIFS(Griffin!B16:B152,"<>",Griffin!M16:M152,"Late") -> 1 | R8: =IF(N8+O8+Q8=0,"-",TEXT((N8+Q8)/(N8+O8+Q8),"0%")) -> 54% | S8: =COUNTIFS(Johar_Town!B21:B164,"<>",Johar_Town!M21:M164,"Present") -> 5 | T8: =COUNTIFS(Johar_Town!B21:B164,"<>",Johar_Town!M21:M164,"Absent") -> 7 | U8: =COUNTIFS(Johar_Town!B21:B164,"<>",Johar_Town!M21:M164,"Leave") -> 7 | V8: =COUNTIFS(Johar_Town!B21:B164,"<>",Johar_Town!M21:M164,"Late") -> 13 | W8: =IF(S8+T8+V8=0,"-",TEXT((S8+V8)/(S8+T8+V8),"0%")) -> 72% | X8: =COUNTIFS(Gulshan_Ravi!B23:B150,"<>",Gulshan_Ravi!M23:M150,"Present") -> 12 | Y8: =COUNTIFS(Gulshan_Ravi!B23:B150,"<>",Gulshan_Ravi!M23:M150,"Absent") -> 4 | Z8: =COUNTIFS(Gulshan_Ravi!B23:B150,"<>",Gulshan_Ravi!M23:M150,"Leave") -> 0 | AA8: =COUNTIFS(Gulshan_Ravi!B23:B150,"<>",Gulshan_Ravi!M23:M150,"Late") -> 13 | AB8: =IF(X8+Y8+AA8=0,"-",TEXT((X8+AA8)/(X8+Y8+AA8),"0%")) -> 86% | AC8: =COUNTIFS(State_Life!B18:B150,"<>",State_Life!M18:M150,"Present") -> 9 | AD8: =COUNTIFS(State_Life!B18:B150,"<>",State_Life!M18:M150,"Absent") -> 5 | AE8: =COUNTIFS(State_Life!B18:B150,"<>",State_Life!M18:M150,"Leave") -> 1 | AF8: =COUNTIFS(State_Life!B18:B150,"<>",State_Life!M18:M150,"Late") -> 2 | AG8: =IF(AC8+AD8+AF8=0,"-",TEXT((AC8+AF8)/(AC8+AD8+AF8),"0%")) -> 69% | AH8: =D8+I8+N8+S8+X8+AC8 -> 59 | AI8: =E8+J8+O8+T8+Y8+AD8 -> 65 | AJ8: =F8+K8+P8+U8+Z8+AE8 -> 18 | AK8: =IF(AH8+AI8=0,"-",TEXT((AH8+(G8+L8+Q8+V8+AA8+AF8))/((D8+I8+N8+S8+X8+AC8)+(G8+L8+Q8+V8+AA8+AF8)+(E8+J8+O8+T8+Y8+AD8)),"0%")) -> 62%
A9: 6 | B9: 07 Jun 2026 | C9: Sunday | D9: =COUNTIFS(Gulberg!B26:B149,"<>",Gulberg!N26:N149,"Present") -> 10 | E9: =COUNTIFS(Gulberg!B26:B149,"<>",Gulberg!N26:N149,"Absent") -> 11 | F9: =COUNTIFS(Gulberg!B26:B149,"<>",Gulberg!N26:N149,"Leave") -> 6 | G9: =COUNTIFS(Gulberg!B26:B149,"<>",Gulberg!N26:N149,"Late") -> 24 | H9: =IF(D9+E9+G9=0,"-",TEXT((D9+G9)/(D9+E9+G9),"0%")) -> 76% | I9: =COUNTIFS(Gulshan_Iqbal!B21:B150,"<>",Gulshan_Iqbal!N21:N150,"Present") -> 13 | J9: =COUNTIFS(Gulshan_Iqbal!B21:B150,"<>",Gulshan_Iqbal!N21:N150,"Absent") -> 19 | K9: =COUNTIFS(Gulshan_Iqbal!B21:B150,"<>",Gulshan_Iqbal!N21:N150,"Leave") -> 4 | L9: =COUNTIFS(Gulshan_Iqbal!B21:B150,"<>",Gulshan_Iqbal!N21:N150,"Late") -> 6 | M9: =IF(I9+J9+L9=0,"-",TEXT((I9+L9)/(I9+J9+L9),"0%")) -> 50% | N9: =COUNTIFS(Griffin!B16:B152,"<>",Griffin!N16:N152,"Present") -> 2 | O9: =COUNTIFS(Griffin!B16:B152,"<>",Griffin!N16:N152,"Absent") -> 14 | P9: =COUNTIFS(Griffin!B16:B152,"<>",Griffin!N16:N152,"Leave") -> 0 | Q9: =COUNTIFS(Griffin!B16:B152,"<>",Griffin!N16:N152,"Late") -> 13 | R9: =IF(N9+O9+Q9=0,"-",TEXT((N9+Q9)/(N9+O9+Q9),"0%")) -> 52% | S9: =COUNTIFS(Johar_Town!B21:B164,"<>",Johar_Town!N21:N164,"Present") -> 6 | T9: =COUNTIFS(Johar_Town!B21:B164,"<>",Johar_Town!N21:N164,"Absent") -> 8 | U9: =COUNTIFS(Johar_Town!B21:B164,"<>",Johar_Town!N21:N164,"Leave") -> 3 | V9: =COUNTIFS(Johar_Town!B21:B164,"<>",Johar_Town!N21:N164,"Late") -> 16 | W9: =IF(S9+T9+V9=0,"-",TEXT((S9+V9)/(S9+T9+V9),"0%")) -> 73% | X9: =COUNTIFS(Gulshan_Ravi!B23:B150,"<>",Gulshan_Ravi!N23:N150,"Present") -> 13 | Y9: =COUNTIFS(Gulshan_Ravi!B23:B150,"<>",Gulshan_Ravi!N23:N150,"Absent") -> 5 | Z9: =COUNTIFS(Gulshan_Ravi!B23:B150,"<>",Gulshan_Ravi!N23:N150,"Leave") -> 0 | AA9: =COUNTIFS(Gulshan_Ravi!B23:B150,"<>",Gulshan_Ravi!N23:N150,"Late") -> 11 | AB9: =IF(X9+Y9+AA9=0,"-",TEXT((X9+AA9)/(X9+Y9+AA9),"0%")) -> 83% | AC9: =COUNTIFS(State_Life!B18:B150,"<>",State_Life!N18:N150,"Present") -> 3 | AD9: =COUNTIFS(State_Life!B18:B150,"<>",State_Life!N18:N150,"Absent") -> 7 | AE9: =COUNTIFS(State_Life!B18:B150,"<>",State_Life!N18:N150,"Leave") -> 0 | AF9: =COUNTIFS(State_Life!B18:B150,"<>",State_Life!N18:N150,"Late") -> 7 | AG9: =IF(AC9+AD9+AF9=0,"-",TEXT((AC9+AF9)/(AC9+AD9+AF9),"0%")) -> 59% | AH9: =D9+I9+N9+S9+X9+AC9 -> 47 | AI9: =E9+J9+O9+T9+Y9+AD9 -> 64 | AJ9: =F9+K9+P9+U9+Z9+AE9 -> 13 | AK9: =IF(AH9+AI9=0,"-",TEXT((AH9+(G9+L9+Q9+V9+AA9+AF9))/((D9+I9+N9+S9+X9+AC9)+(G9+L9+Q9+V9+AA9+AF9)+(E9+J9+O9+T9+Y9+AD9)),"0%")) -> 66%
